Workbook

Sheet RawData
A1: SerialNo | B1: BomNo | C1: UnitType | D1: ModelNo | E1: TestDate | F1: OverallPassFail | G1: RunTestSuctionTubeTemp | H1: RunTestEvapInletRetBendATemp | I1: RunTestEvapInletRetBendBTemp | J1: RunTestEvapOutletAirTemp | K1: RunTestEvap_B_OutletAirTemp | L1: RunTestInletOutletAirTempDelta | M1: RunTestInletOutlet_B_AirTempDelta | N1: RunTestAmbientTemperature | O1: RunTestVoltageStartup | P1: RunTestFinalVoltage | Q1: RunTestCurrentStartup | R1: RunTestFinalCurrent | S1: Z_RunTestSuctionTubeTemp | T1: Z_RunTestEvapInletRetBendATemp | U1: Z_RunTestEvapInletRetBendBTemp | V1: Z_RunTestEvapOutletAirTemp | W1: Z_RunTestEvap_B_OutletAirTemp | X1: Z_RunTestInletOutletAirTempDelta | Y1: Z_RunTestInletOutlet_B_AirTempDelta | Z1: Z_RunTestAmbientTemperature | AA1: Z_RunTestVoltageStartup | AB1: Z_RunTestFinalVoltage | AC1: Z_RunTestCurrentStartup | AD1: Z_RunTestFinalCurrent
A2: 04M1925120154 | B2: CRS0000675 | C2: LT | D2: ALX440U-DS3B01 | E2: 46010 | F2: Fail | G2: 0 | H2: 0 | I2: 0 | J2: 0 | K2: 0 | L2: 0 | M2: 0 | N2: 0 | O2: 110.54 | P2: 0 | Q2: 9.01 | R2: 0 | S2: =IF(OR(G2=0,G2=""),"",ABS((G2-IF($C2="LT",Config!$F$2,Config!$F$14))/IF($C2="LT",Config!$G$2,Config!$G$14))) | T2: =IF(OR(H2=0,H2=""),"",ABS((H2-IF($C2="LT",Config!$F$3,Config!$F$15))/IF($C2="LT",Config!$G$3,Config!$G$15))) | U2: =IF(OR(I2=0,I2=""),"",ABS((I2-IF($C2="LT",Config!$F$4,Config!$F$16))/IF($C2="LT",Config!$G$4,Config!$G$16))) | V2: =IF(OR(J2=0,J2=""),"",ABS((J2-IF($C2="LT",Config!$F$5,Config!$F$17))/IF($C2="LT",Config!$G$5,Config!$G$17))) | W2: =IF(OR(K2=0,K2=""),"",ABS((K2-IF($C2="LT",Config!$F$6,Config!$F$18))/IF($C2="LT",Config!$G$6,Config!$G$18))) | X2: =IF(OR(L2=0,L2=""),"",ABS((L2-IF($C2="LT",Config!$F$7,Config!$F$19))/IF($C2="LT",Config!$G$7,Config!$G$19))) | Y2: =IF(OR(M2=0,M2=""),"",ABS((M2-IF($C2="LT",Config!$F$8,Config!$F$20))/IF($C2="LT",Config!$G$8,Config!$G$20))) | Z2: =IF(OR(N2=0,N2=""),"",ABS((N2-IF($C2="LT",Config!$F$9,Config!$F$21))/IF($C2="LT",Config!$G$9,Config!$G$21))) | AA2: =IF(OR(O2=0,O2=""),"",ABS((O2-IF($C2="LT",Config!$F$10,Config!$F$22))/IF($C2="LT",Config!$G$10,Config!$G$22))) | AB2: =IF(OR(P2=0,P2=""),"",ABS((P2-IF($C2="LT",Config!$F$11,Config!$F$23))/IF($C2="LT",Config!$G$11,Config!$G$23))) | AC2: =IF(OR(Q2=0,Q2=""),"",ABS((Q2-IF($C2="LT",Config!$F$12,Config!$F$24))/IF($C2="LT",Config!$G$12,Config!$G$24))) | AD2: =IF(OR(R2=0,R2=""),"",ABS((R2-IF($C2="LT",Config!$F$13,Config!$F$25))/IF($C2="LT",Config!$G$13,Config!$G$25)))
A3: 04M1925120154 | B3: CRS0000675 | C3: LT | D3: ALX440U-DS3B01 | E3: 46010 | F3: Fail | G3: 0 | H3: 0 | I3: 0 | J3: 0 | K3: 0 | L3: 0 | M3: 0 | N3: 0 | O3: 0 | P3: 0 | Q3: 0 | R3: 0 | S3: =IF(OR(G3=0,G3=""),"",ABS((G3-IF($C3="LT",Config!$F$2,Config!$F$14))/IF($C3="LT",Config!$G$2,Config!$G$14))) | T3: =IF(OR(H3=0,H3=""),"",ABS((H3-IF($C3="LT",Config!$F$3,Config!$F$15))/IF($C3="LT",Config!$G$3,Config!$G$15))) | U3: =IF(OR(I3=0,I3=""),"",ABS((I3-IF($C3="LT",Config!$F$4,Config!$F$16))/IF($C3="LT",Config!$G$4,Config!$G$16))) | V3: =IF(OR(J3=0,J3=""),"",ABS((J3-IF($C3="LT",Config!$F$5,Config!$F$17))/IF($C3="LT",Config!$G$5,Config!$G$17))) | W3: =IF(OR(K3=0,K3=""),"",ABS((K3-IF($C3="LT",Config!$F$6,Config!$F$18))/IF($C3="LT",Config!$G$6,Config!$G$18))) | X3: =IF(OR(L3=0,L3=""),"",ABS((L3-IF($C3="LT",Config!$F$7,Config!$F$19))/IF($C3="LT",Config!$G$7,Config!$G$19))) | Y3: =IF(OR(M3=0,M3=""),"",ABS((M3-IF($C3="LT",Config!$F$8,Config!$F$20))/IF($C3="LT",Config!$G$8,Config!$G$20))) | Z3: =IF(OR(N3=0,N3=""),"",ABS((N3-IF($C3="LT",Config!$F$9,Config!$F$21))/IF($C3="LT",Config!$G$9,Config!$G$21))) | AA3: =IF(OR(O3=0,O3=""),"",ABS((O3-IF($C3="LT",Config!$F$10,Config!$F$22))/IF($C3="LT",Config!$G$10,Config!$G$22))) | AB3: =IF(OR(P3=0,P3=""),"",ABS((P3-IF($C3="LT",Config!$F$11,Config!$F$23))/IF($C3="LT",Config!$G$11,Config!$G$23))) | AC3: =IF(OR(Q3=0,Q3=""),"",ABS((Q3-IF($C3="LT",Config!$F$12,Config!$F$24))/IF($C3="LT",Config!$G$12,Config!$G$24))) | AD3: =IF(OR(R3=0,R3=""),"",ABS((R3-IF($C3="LT",Config!$F$13,Config!$F$25))/IF($C3="LT",Config!$G$13,Config!$G$25)))
A4: 04M1925120154 | B4: CRS0000675 | C4: LT | D4: ALX440U-DS3B01 | E4: 46010 | F4: Fail | G4: 0 | H4: 0 | I4: 0 | J4: 0 | K4: 0 | L4: 0 | M4: 0 | N4: 0 | O4: 110.76 | P4: 0 | Q4: 8.69 | R4: 0 | S4: =IF(OR(G4=0,G4=""),"",ABS((G4-IF($C4="LT",Config!$F$2,Config!$F$14))/IF($C4="LT",Config!$G$2,Config!$G$14))) | T4: =IF(OR(H4=0,H4=""),"",ABS((H4-IF($C4="LT",Config!$F$3,Config!$F$15))/IF($C4="LT",Config!$G$3,Config!$G$15))) | U4: =IF(OR(I4=0,I4=""),"",ABS((I4-IF($C4="LT",Config!$F$4,Config!$F$16))/IF($C4="LT",Config!$G$4,Config!$G$16))) | V4: =IF(OR(J4=0,J4=""),"",ABS((J4-IF($C4="LT",Config!$F$5,Config!$F$17))/IF($C4="LT",Config!$G$5,Config!$G$17))) | W4: =IF(OR(K4=0,K4=""),"",ABS((K4-IF($C4="LT",Config!$F$6,Config!$F$18))/IF($C4="LT",Config!$G$6,Config!$G$18))) | X4: =IF(OR(L4=0,L4=""),"",ABS((L4-IF($C4="LT",Config!$F$7,Config!$F$19))/IF($C4="LT",Config!$G$7,Config!$G$19))) | Y4: =IF(OR(M4=0,M4=""),"",ABS((M4-IF($C4="LT",Config!$F$8,Config!$F$20))/IF($C4="LT",Config!$G$8,Config!$G$20))) | Z4: =IF(OR(N4=0,N4=""),"",ABS((N4-IF($C4="LT",Config!$F$9,Config!$F$21))/IF($C4="LT",Config!$G$9,Config!$G$21))) | AA4: =IF(OR(O4=0,O4=""),"",ABS((O4-IF($C4="LT",Config!$F$10,Config!$F$22))/IF($C4="LT",Config!$G$10,Config!$G$22))) | AB4: =IF(OR(P4=0,P4=""),"",ABS((P4-IF($C4="LT",Config!$F$11,Config!$F$23))/IF($C4="LT",Config!$G$11,Config!$G$23))) | AC4: =IF(OR(Q4=0,Q4=""),"",ABS((Q4-IF($C4="LT",Config!$F$12,Config!$F$24))/IF($C4="LT",Config!$G$12,Config!$G$24))) | AD4: =IF(OR(R4=0,R4=""),"",ABS((R4-IF($C4="LT",Config!$F$13,Config!$F$25))/IF($C4="LT",Config!$G$13,Config!$G$25)))
A5: 04M2225120168 | B5: CRS0000675 | C5: LT | D5: ALX440U-DS3B01 | E5: 46036 | F5: Fail | G5: 152.6 | H5: 79.8 | I5: -1957.8 | J5: 65.5 | K5: 0 | L5: 2.6 | M5: 0 | N5: 68.1 | O5: 114.94 | P5: 114.72 | Q5: 7.5 | R5: 8.08 | S5: =IF(OR(G5=0,G5=""),"",ABS((G5-IF($C5="LT",Config!$F$2,Config!$F$14))/IF($C5="LT",Config!$G$2,Config!$G$14))) | T5: =IF(OR(H5=0,H5=""),"",ABS((H5-IF($C5="LT",Config!$F$3,Config!$F$15))/IF($C5="LT",Config!$G$3,Config!$G$15))) | U5: =IF(OR(I5=0,I5=""),"",ABS((I5-IF($C5="LT",Config!$F$4,Config!$F$16))/IF($C5="LT",Config!$G$4,Config!$G$16))) | V5: =IF(OR(J5=0,J5=""),"",ABS((J5-IF($C5="LT",Config!$F$5,Config!$F$17))/IF($C5="LT",Config!$G$5,Config!$G$17))) | W5: =IF(OR(K5=0,K5=""),"",ABS((K5-IF($C5="LT",Config!$F$6,Config!$F$18))/IF($C5="LT",Config!$G$6,Config!$G$18))) | X5: =IF(OR(L5=0,L5=""),"",ABS((L5-IF($C5="LT",Config!$F$7,Config!$F$19))/IF($C5="LT",Config!$G$7,Config!$G$19))) | Y5: =IF(OR(M5=0,M5=""),"",ABS((M5-IF($C5="LT",Config!$F$8,Config!$F$20))/IF($C5="LT",Config!$G$8,Config!$G$20))) | Z5: =IF(OR(N5=0,N5=""),"",ABS((N5-IF($C5="LT",Config!$F$9,Config!$F$21))/IF($C5="LT",Config!$G$9,Config!$G$21))) | AA5: =IF(OR(O5=0,O5=""),"",ABS((O5-IF($C5="LT",Config!$F$10,Config!$F$22))/IF($C5="LT",Config!$G$10,Config!$G$22))) | AB5: =IF(OR(P5=0,P5=""),"",ABS((P5-IF($C5="LT",Config!$F$11,Config!$F$23))/IF($C5="LT",Config!$G$11,Config!$G$23))) | AC5: =IF(OR(Q5=0,Q5=""),"",ABS((Q5-IF($C5="LT",Config!$F$12,Config!$F$24))/IF($C5="LT",Config!$G$12,Config!$G$24))) | AD5: =IF(OR(R5=0,R5=""),"",ABS((R5-IF($C5="LT",Config!$F$13,Config!$F$25))/IF($C5="LT",Config!$G$13,Config!$G$25)))
A6: 04M2225120168 | B6: CRS0000675 | C6: LT | D6: ALX440U-DS3B01 | E6: 46036 | F6: Fail | G6: 154.8 | H6: 91 | I6: -1957.8 | J6: 65.9 | K6: 0 | L6: 5.5 | M6: 0 | N6: 71.4 | O6: 111.35 | P6: 113.11 | Q6: 8.13 | R6: 8.18 | S6: =IF(OR(G6=0,G6=""),"",ABS((G6-IF($C6="LT",Config!$F$2,Config!$F$14))/IF($C6="LT",Config!$G$2,Config!$G$14))) | T6: =IF(OR(H6=0,H6=""),"",ABS((H6-IF($C6="LT",Config!$F$3,Config!$F$15))/IF($C6="LT",Config!$G$3,Config!$G$15))) | U6: =IF(OR(I6=0,I6=""),"",ABS((I6-IF($C6="LT",Config!$F$4,Config!$F$16))/IF($C6="LT",Config!$G$4,Config!$G$16))) | V6: =IF(OR(J6=0,J6=""),"",ABS((J6-IF($C6="LT",Config!$F$5,Config!$F$17))/IF($C6="LT",Config!$G$5,Config!$G$17))) | W6: =IF(OR(K6=0,K6=""),"",ABS((K6-IF($C6="LT",Config!$F$6,Config!$F$18))/IF($C6="LT",Config!$G$6,Config!$G$18))) | X6: =IF(OR(L6=0,L6=""),"",ABS((L6-IF($C6="LT",Config!$F$7,Config!$F$19))/IF($C6="LT",Config!$G$7,Config!$G$19))) | Y6: =IF(OR(M6=0,M6=""),"",ABS((M6-IF($C6="LT",Config!$F$8,Config!$F$20))/IF($C6="LT",Config!$G$8,Config!$G$20))) | Z6: =IF(OR(N6=0,N6=""),"",ABS((N6-IF($C6="LT",Config!$F$9,Config!$F$21))/IF($C6="LT",Config!$G$9,Config!$G$21))) | AA6: =IF(OR(O6=0,O6=""),"",ABS((O6-IF($C6="LT",Config!$F$10,Config!$F$22))/IF($C6="LT",Config!$G$10,Config!$G$22))) | AB6: =IF(OR(P6=0,P6=""),"",ABS((P6-IF($C6="LT",Config!$F$11,Config!$F$23))/IF($C6="LT",Config!$G$11,Config!$G$23))) | AC6: =IF(OR(Q6=0,Q6=""),"",ABS((Q6-IF($C6="LT",Config!$F$12,Config!$F$24))/IF($C6="LT",Config!$G$12,Config!$G$24))) | AD6: =IF(OR(R6=0,R6=""),"",ABS((R6-IF($C6="LT",Config!$F$13,Config!$F$25))/IF($C6="LT",Config!$G$13,Config!$G$25)))
A7: 04M2225120168 | B7: CRS0000675 | C7: LT | D7: ALX440U-DS3B01 | E7: 46036 | F7: Fail | G7: 143.2 | H7: 91.5 | I7: -1957.8 | J7: 66.4 | K7: 0 | L7: 3.5 | M7: 0 | N7: 69.9 | O7: 111.79 | P7: 113.18 | Q7: 8.13 | R7: 8.37 | S7: =IF(OR(G7=0,G7=""),"",ABS((G7-IF($C7="LT",Config!$F$2,Config!$F$14))/IF($C7="LT",Config!$G$2,Config!$G$14))) | T7: =IF(OR(H7=0,H7=""),"",ABS((H7-IF($C7="LT",Config!$F$3,Config!$F$15))/IF($C7="LT",Config!$G$3,Config!$G$15))) | U7: =IF(OR(I7=0,I7=""),"",ABS((I7-IF($C7="LT",Config!$F$4,Config!$F$16))/IF($C7="LT",Config!$G$4,Config!$G$16))) | V7: =IF(OR(J7=0,J7=""),"",ABS((J7-IF($C7="LT",Config!$F$5,Config!$F$17))/IF($C7="LT",Config!$G$5,Config!$G$17))) | W7: =IF(OR(K7=0,K7=""),"",ABS((K7-IF($C7="LT",Config!$F$6,Config!$F$18))/IF($C7="LT",Config!$G$6,Config!$G$18))) | X7: =IF(OR(L7=0,L7=""),"",ABS((L7-IF($C7="LT",Config!$F$7,Config!$F$19))/IF($C7="LT",Config!$G$7,Config!$G$19))) | Y7: =IF(OR(M7=0,M7=""),"",ABS((M7-IF($C7="LT",Config!$F$8,Config!$F$20))/IF($C7="LT",Config!$G$8,Config!$G$20))) | Z7: =IF(OR(N7=0,N7=""),"",ABS((N7-IF($C7="LT",Config!$F$9,Config!$F$21))/IF($C7="LT",Config!$G$9,Config!$G$21))) | AA7: =IF(OR(O7=0,O7=""),"",ABS((O7-IF($C7="LT",Config!$F$10,Config!$F$22))/IF($C7="LT",Config!$G$10,Config!$G$22))) | AB7: =IF(OR(P7=0,P7=""),"",ABS((P7-IF($C7="LT",Config!$F$11,Config!$F$23))/IF($C7="LT",Config!$G$11,Config!$G$23))) | AC7: =IF(OR(Q7=0,Q7=""),"",ABS((Q7-IF($C7="LT",Config!$F$12,Config!$F$24))/IF($C7="LT",Config!$G$12,Config!$G$24))) | AD7: =IF(OR(R7=0,R7=""),"",ABS((R7-IF($C7="LT",Config!$F$13,Config!$F$25))/IF($C7="LT",Config!$G$13,Config!$G$25)))
A8: 04M2225120168 | B8: CRS0000675 | C8: LT | D8: ALX440U-DS3B01 | E8: 46036 | F8: Fail | G8: 149.9 | H8: 90.6 | I8: -1957.8 | J8: 66.4 | K8: 0 | L8: 2.8 | M8: 0 | N8: 69.2 | O8: 114.94 | P8: 114.87 | Q8: 7.79 | R8: 8.25 | S8: =IF(OR(G8=0,G8=""),"",ABS((G8-IF($C8="LT",Config!$F$2,Config!$F$14))/IF($C8="LT",Config!$G$2,Config!$G$14))) | T8: =IF(OR(H8=0,H8=""),"",ABS((H8-IF($C8="LT",Config!$F$3,Config!$F$15))/IF($C8="LT",Config!$G$3,Config!$G$15))) | U8: =IF(OR(I8=0,I8=""),"",ABS((I8-IF($C8="LT",Config!$F$4,Config!$F$16))/IF($C8="LT",Config!$G$4,Config!$G$16))) | V8: =IF(OR(J8=0,J8=""),"",ABS((J8-IF($C8="LT",Config!$F$5,Config!$F$17))/IF($C8="LT",Config!$G$5,Config!$G$17))) | W8: =IF(OR(K8=0,K8=""),"",ABS((K8-IF($C8="LT",Config!$F$6,Config!$F$18))/IF($C8="LT",Config!$G$6,Config!$G$18))) | X8: =IF(OR(L8=0,L8=""),"",ABS((L8-IF($C8="LT",Config!$F$7,Config!$F$19))/IF($C8="LT",Config!$G$7,Config!$G$19))) | Y8: =IF(OR(M8=0,M8=""),"",ABS((M8-IF($C8="LT",Config!$F$8,Config!$F$20))/IF($C8="LT",Config!$G$8,Config!$G$20))) | Z8: =IF(OR(N8=0,N8=""),"",ABS((N8-IF($C8="LT",Config!$F$9,Config!$F$21))/IF($C8="LT",Config!$G$9,Config!$G$21))) | AA8: =IF(OR(O8=0,O8=""),"",ABS((O8-IF($C8="LT",Config!$F$10,Config!$F$22))/IF($C8="LT",Config!$G$10,Config!$G$22))) | AB8: =IF(OR(P8=0,P8=""),"",ABS((P8-IF($C8="LT",Config!$F$11,Config!$F$23))/IF($C8="LT",Config!$G$11,Config!$G$23))) | AC8: =IF(OR(Q8=0,Q8=""),"",ABS((Q8-IF($C8="LT",Config!$F$12,Config!$F$24))/IF($C8="LT",Config!$G$12,Config!$G$24))) | AD8: =IF(OR(R8=0,R8=""),"",ABS((R8-IF($C8="LT",Config!$F$13,Config!$F$25))/IF($C8="LT",Config!$G$13,Config!$G$25)))
A9: 04M2225120168 | B9: CRS0000675 | C9: LT | D9: ALX440U-DS3B01 | E9: 46038 | F9: Fail | G9: 145 | H9: 84.3 | I9: -1957.8 | J9: 63.7 | K9: 0 | L9: 8 | M9: 0 | N9: 71.7 | O9: 114.94 | P9: 114.72 | Q9: 7.01 | R9: 7.25 | S9: =IF(OR(G9=0,G9=""),"",ABS((G9-IF($C9="LT",Config!$F$2,Config!$F$14))/IF($C9="LT",Config!$G$2,Config!$G$14))) | T9: =IF(OR(H9=0,H9=""),"",ABS((H9-IF($C9="LT",Config!$F$3,Config!$F$15))/IF($C9="LT",Config!$G$3,Config!$G$15))) | U9: =IF(OR(I9=0,I9=""),"",ABS((I9-IF($C9="LT",Config!$F$4,Config!$F$16))/IF($C9="LT",Config!$G$4,Config!$G$16))) | V9: =IF(OR(J9=0,J9=""),"",ABS((J9-IF($C9="LT",Config!$F$5,Config!$F$17))/IF($C9="LT",Config!$G$5,Config!$G$17))) | W9: =IF(OR(K9=0,K9=""),"",ABS((K9-IF($C9="LT",Config!$F$6,Config!$F$18))/IF($C9="LT",Config!$G$6,Config!$G$18))) | X9: =IF(OR(L9=0,L9=""),"",ABS((L9-IF($C9="LT",Config!$F$7,Config!$F$19))/IF($C9="LT",Config!$G$7,Config!$G$19))) | Y9: =IF(OR(M9=0,M9=""),"",ABS((M9-IF($C9="LT",Config!$F$8,Config!$F$20))/IF($C9="LT",Config!$G$8,Config!$G$20))) | Z9: =IF(OR(N9=0,N9=""),"",ABS((N9-IF($C9="LT",Config!$F$9,Config!$F$21))/IF($C9="LT",Config!$G$9,Config!$G$21))) | AA9: =IF(OR(O9=0,O9=""),"",ABS((O9-IF($C9="LT",Config!$F$10,Config!$F$22))/IF($C9="LT",Config!$G$10,Config!$G$22))) | AB9: =IF(OR(P9=0,P9=""),"",ABS((P9-IF($C9="LT",Config!$F$11,Config!$F$23))/IF($C9="LT",Config!$G$11,Config!$G$23))) | AC9: =IF(OR(Q9=0,Q9=""),"",ABS((Q9-IF($C9="LT",Config!$F$12,Config!$F$24))/IF($C9="LT",Config!$G$12,Config!$G$24))) | AD9: =IF(OR(R9=0,R9=""),"",ABS((R9-IF($C9="LT",Config!$F$13,Config!$F$25))/IF($C9="LT",Config!$G$13,Config!$G$25)))
A10: 04M2225120168 | B10: CRS0000675 | C10: LT | D10: ALX440U-DS3B01 | E10: 46038 | F10: Fail | G10: 148.1 | H10: 86.1 | I10: -1957.8 | J10: 63.7 | K10: 0 | L10: 8.1 | M10: 0 | N10: 71.8 | O10: 114.87 | P10: 114.8 | Q10: 7.23 | R10: 7.45 | S10: =IF(OR(G10=0,G10=""),"",ABS((G10-IF($C10="LT",Config!$F$2,Config!$F$14))/IF($C10="LT",Config!$G$2,Config!$G$14))) | T10: =IF(OR(H10=0,H10=""),"",ABS((H10-IF($C10="LT",Config!$F$3,Config!$F$15))/IF($C10="LT",Config!$G$3,Config!$G$15))) | U10: =IF(OR(I10=0,I10=""),"",ABS((I10-IF($C10="LT",Config!$F$4,Config!$F$16))/IF($C10="LT",Config!$G$4,Config!$G$16))) | V10: =IF(OR(J10=0,J10=""),"",ABS((J10-IF($C10="LT",Config!$F$5,Config!$F$17))/IF($C10="LT",Config!$G$5,Config!$G$17))) | W10: =IF(OR(K10=0,K10=""),"",ABS((K10-IF($C10="LT",Config!$F$6,Config!$F$18))/IF($C10="LT",Config!$G$6,Config!$G$18))) | X10: =IF(OR(L10=0,L10=""),"",ABS((L10-IF($C10="LT",Config!$F$7,Config!$F$19))/IF($C10="LT",Config!$G$7,Config!$G$19))) | Y10: =IF(OR(M10=0,M10=""),"",ABS((M10-IF($C10="LT",Config!$F$8,Config!$F$20))/IF($C10="LT",Config!$G$8,Config!$G$20))) | Z10: =IF(OR(N10=0,N10=""),"",ABS((N10-IF($C10="LT",Config!$F$9,Config!$F$21))/IF($C10="LT",Config!$G$9,Config!$G$21))) | AA10: =IF(OR(O10=0,O10=""),"",ABS((O10-IF($C10="LT",Config!$F$10,Config!$F$22))/IF($C10="LT",Config!$G$10,Config!$G$22))) | AB10: =IF(OR(P10=0,P10=""),"",ABS((P10-IF($C10="LT",Config!$F$11,Config!$F$23))/IF($C10="LT",Config!$G$11,Config!$G$23))) | AC10: =IF(OR(Q10=0,Q10=""),"",ABS((Q10-IF($C10="LT",Config!$F$12,Config!$F$24))/IF($C10="LT",Config!$G$12,Config!$G$24))) | AD10: =IF(OR(R10=0,R10=""),"",ABS((R10-IF($C10="LT",Config!$F$13,Config!$F$25))/IF($C10="LT",Config!$G$13,Config!$G$25)))
A11: 04M2225120168 | B11: CRS0000675 | C11: LT | D11: ALX440U-DS3B01 | E11: 46038 | F11: Fail | G11: 140.5 | H11: 93.3 | I11: -1957.8 | J11: -1952 | K11: 0 | L11: 2024 | M11: 0 | N11: 72 | O11: 111.79 | P11: 113.62 | Q11: 7.96 | R11: 7.93 | S11: =IF(OR(G11=0,G11=""),"",ABS((G11-IF($C11="LT",Config!$F$2,Config!$F$14))/IF($C11="LT",Config!$G$2,Config!$G$14))) | T11: =IF(OR(H11=0,H11=""),"",ABS((H11-IF($C11="LT",Config!$F$3,Config!$F$15))/IF($C11="LT",Config!$G$3,Config!$G$15))) | U11: =IF(OR(I11=0,I11=""),"",ABS((I11-IF($C11="LT",Config!$F$4,Config!$F$16))/IF($C11="LT",Config!$G$4,Config!$G$16))) | V11: =IF(OR(J11=0,J11=""),"",ABS((J11-IF($C11="LT",Config!$F$5,Config!$F$17))/IF($C11="LT",Config!$G$5,Config!$G$17))) | W11: =IF(OR(K11=0,K11=""),"",ABS((K11-IF($C11="LT",Config!$F$6,Config!$F$18))/IF($C11="LT",Config!$G$6,Config!$G$18))) | X11: =IF(OR(L11=0,L11=""),"",ABS((L11-IF($C11="LT",Config!$F$7,Config!$F$19))/IF($C11="LT",Config!$G$7,Config!$G$19))) | Y11: =IF(OR(M11=0,M11=""),"",ABS((M11-IF($C11="LT",Config!$F$8,Config!$F$20))/IF($C11="LT",Config!$G$8,Config!$G$20))) | Z11: =IF(OR(N11=0,N11=""),"",ABS((N11-IF($C11="LT",Config!$F$9,Config!$F$21))/IF($C11="LT",Config!$G$9,Config!$G$21))) | AA11: =IF(OR(O11=0,O11=""),"",ABS((O11-IF($C11="LT",Config!$F$10,Config!$F$22))/IF($C11="LT",Config!$G$10,Config!$G$22))) | AB11: =IF(OR(P11=0,P11=""),"",ABS((P11-IF($C11="LT",Config!$F$11,Config!$F$23))/IF($C11="LT",Config!$G$11,Config!$G$23))) | AC11: =IF(OR(Q11=0,Q11=""),"",ABS((Q11-IF($C11="LT",Config!$F$12,Config!$F$24))/IF($C11="LT",Config!$G$12,Config!$G$24))) | AD11: =IF(OR(R11=0,R11=""),"",ABS((R11-IF($C11="LT",Config!$F$13,Config!$F$25))/IF($C11="LT",Config!$G$13,Config!$G$25)))
A12: 04M2225120168 | B12: CRS0000675 | C12: LT | D12: ALX440U-DS3B01 | E12: 46038 | F12: Fail | G12: 138.8 | H12: 91.5 | I12: -1957.8 | J12: -1952 | K12: 0 | L12: 2022.7 | M12: 0 | N12: 70.7 | O12: 115.16 | P12: 115.16 | Q12: 7.64 | R12: 7.76 | S12: =IF(OR(G12=0,G12=""),"",ABS((G12-IF($C12="LT",Config!$F$2,Config!$F$14))/IF($C12="LT",Config!$G$2,Config!$G$14))) | T12: =IF(OR(H12=0,H12=""),"",ABS((H12-IF($C12="LT",Config!$F$3,Config!$F$15))/IF($C12="LT",Config!$G$3,Config!$G$15))) | U12: =IF(OR(I12=0,I12=""),"",ABS((I12-IF($C12="LT",Config!$F$4,Config!$F$16))/IF($C12="LT",Config!$G$4,Config!$G$16))) | V12: =IF(OR(J12=0,J12=""),"",ABS((J12-IF($C12="LT",Config!$F$5,Config!$F$17))/IF($C12="LT",Config!$G$5,Config!$G$17))) | W12: =IF(OR(K12=0,K12=""),"",ABS((K12-IF($C12="LT",Config!$F$6,Config!$F$18))/IF($C12="LT",Config!$G$6,Config!$G$18))) | X12: =IF(OR(L12=0,L12=""),"",ABS((L12-IF($C12="LT",Config!$F$7,Config!$F$19))/IF($C12="LT",Config!$G$7,Config!$G$19))) | Y12: =IF(OR(M12=0,M12=""),"",ABS((M12-IF($C12="LT",Config!$F$8,Config!$F$20))/IF($C12="LT",Config!$G$8,Config!$G$20))) | Z12: =IF(OR(N12=0,N12=""),"",ABS((N12-IF($C12="LT",Config!$F$9,Config!$F$21))/IF($C12="LT",Config!$G$9,Config!$G$21))) | AA12: =IF(OR(O12=0,O12=""),"",ABS((O12-IF($C12="LT",Config!$F$10,Config!$F$22))/IF($C12="LT",Config!$G$10,Config!$G$22))) | AB12: =IF(OR(P12=0,P12=""),"",ABS((P12-IF($C12="LT",Config!$F$11,Config!$F$23))/IF($C12="LT",Config!$G$11,Config!$G$23))) | AC12: =IF(OR(Q12=0,Q12=""),"",ABS((Q12-IF($C12="LT",Config!$F$12,Config!$F$24))/IF($C12="LT",Config!$G$12,Config!$G$24))) | AD12: =IF(OR(R12=0,R12=""),"",ABS((R12-IF($C12="LT",Config!$F$13,Config!$F$25))/IF($C12="LT",Config!$G$13,Config!$G$25)))
A13: 04M2225120168 | B13: CRS0000675 | C13: LT | D13: ALX440U-DS3B01 | E13: 46041 | F13: Fail | G13: 154.4 | H13: 89.7 | I13: -1957.8 | J13: 63.3 | K13: 0 | L13: 3 | M13: 0 | N13: 66.3 | O13: 111.5 | P13: 112.74 | Q13: 8.33 | R13: 8.62 | S13: =IF(OR(G13=0,G13=""),"",ABS((G13-IF($C13="LT",Config!$F$2,Config!$F$14))/IF($C13="LT",Config!$G$2,Config!$G$14))) | T13: =IF(OR(H13=0,H13=""),"",ABS((H13-IF($C13="LT",Config!$F$3,Config!$F$15))/IF($C13="LT",Config!$G$3,Config!$G$15))) | U13: =IF(OR(I13=0,I13=""),"",ABS((I13-IF($C13="LT",Config!$F$4,Config!$F$16))/IF($C13="LT",Config!$G$4,Config!$G$16))) | V13: =IF(OR(J13=0,J13=""),"",ABS((J13-IF($C13="LT",Config!$F$5,Config!$F$17))/IF($C13="LT",Config!$G$5,Config!$G$17))) | W13: =IF(OR(K13=0,K13=""),"",ABS((K13-IF($C13="LT",Config!$F$6,Config!$F$18))/IF($C13="LT",Config!$G$6,Config!$G$18))) | X13: =IF(OR(L13=0,L13=""),"",ABS((L13-IF($C13="LT",Config!$F$7,Config!$F$19))/IF($C13="LT",Config!$G$7,Config!$G$19))) | Y13: =IF(OR(M13=0,M13=""),"",ABS((M13-IF($C13="LT",Config!$F$8,Config!$F$20))/IF($C13="LT",Config!$G$8,Config!$G$20))) | Z13: =IF(OR(N13=0,N13=""),"",ABS((N13-IF($C13="LT",Config!$F$9,Config!$F$21))/IF($C13="LT",Config!$G$9,Config!$G$21))) | AA13: =IF(OR(O13=0,O13=""),"",ABS((O13-IF($C13="LT",Config!$F$10,Config!$F$22))/IF($C13="LT",Config!$G$10,Config!$G$22))) | AB13: =IF(OR(P13=0,P13=""),"",ABS((P13-IF($C13="LT",Config!$F$11,Config!$F$23))/IF($C13="LT",Config!$G$11,Config!$G$23))) | AC13: =IF(OR(Q13=0,Q13=""),"",ABS((Q13-IF($C13="LT",Config!$F$12,Config!$F$24))/IF($C13="LT",Config!$G$12,Config!$G$24))) | AD13: =IF(OR(R13=0,R13=""),"",ABS((R13-IF($C13="LT",Config!$F$13,Config!$F$25))/IF($C13="LT",Config!$G$13,Config!$G$25)))
... A941: 04D1426121371 | B941: CRS0000674 | C941: MT | D941: TCX413U-DS1B01 | E941: 46136 | F941: Pass | G941: 119.1 | H941: 79.8 | I941: -1957.8 | J941: 70.8 | K941: 0 | L941: 0.8 | M941: 0 | N941: 70 | O941: 112.08 | P941: 116.7 | Q941: 3.71 | R941: 3.71 | S941: =IF(OR(G941=0,G941=""),"",ABS((G941-IF($C941="LT",Config!$F$2,Config!$F$14))/IF($C941="LT",Config!$G$2,Config!$G$14))) | T941: =IF(OR(H941=0,H941=""),"",ABS((H941-IF($C941="LT",Config!$F$3,Config!$F$15))/IF($C941="LT",Config!$G$3,Config!$G$15))) | U941: =IF(OR(I941=0,I941=""),"",ABS((I941-IF($C941="LT",Config!$F$4,Config!$F$16))/IF($C941="LT",Config!$G$4,Config!$G$16))) | V941: =IF(OR(J941=0,J941=""),"",ABS((J941-IF($C941="LT",Config!$F$5,Config!$F$17))/IF($C941="LT",Config!$G$5,Config!$G$17))) | W941: =IF(OR(K941=0,K941=""),"",ABS((K941-IF($C941="LT",Config!$F$6,Config!$F$18))/IF($C941="LT",Config!$G$6,Config!$G$18))) | X941: =IF(OR(L941=0,L941=""),"",ABS((L941-IF($C941="LT",Config!$F$7,Config!$F$19))/IF($C941="LT",Config!$G$7,Config!$G$19))) | Y941: =IF(OR(M941=0,M941=""),"",ABS((M941-IF($C941="LT",Config!$F$8,Config!$F$20))/IF($C941="LT",Config!$G$8,Config!$G$20))) | Z941: =IF(OR(N941=0,N941=""),"",ABS((N941-IF($C941="LT",Config!$F$9,Config!$F$21))/IF($C941="LT",Config!$G$9,Config!$G$21))) | AA941: =IF(OR(O941=0,O941=""),"",ABS((O941-IF($C941="LT",Config!$F$10,Config!$F$22))/IF($C941="LT",Config!$G$10,Config!$G$22))) | AB941: =IF(OR(P941=0,P941=""),"",ABS((P941-IF($C941="LT",Config!$F$11,Config!$F$23))/IF($C941="LT",Config!$G$11,Config!$G$23))) | AC941: =IF(OR(Q941=0,Q941=""),"",ABS((Q941-IF($C941="LT",Config!$F$12,Config!$F$24))/IF($C941="LT",Config!$G$12,Config!$G$24))) | AD941: =IF(OR(R941=0,R941=""),"",ABS((R941-IF($C941="LT",Config!$F$13,Config!$F$25))/IF($C941="LT",Config!$G$13,Config!$G$25)))

Sheet Config
A1: Unit | B1: Measurement | C1: RawDataCol | D1: n_all | E1: n_pass | F1: Mean_pass | G1: StdDev_pass | H1: Min_all | I1: Max_all | J1: BinWidth | K1: BinStart
A2: LT | B2: Suction Tube Temp | C2: G | D2: =COUNTIFS(RawData!$C$2:$C$941,"LT",RawData!$G$2:$G$941,"<>0") | E2: =COUNTIFS(RawData!$C$2:$C$941,"LT",RawData!$F$2:$F$941,"Pass",RawData!$G$2:$G$941,"<>0") | F2: =IFERROR(AVERAGEIFS(RawData!$G$2:$G$941,RawData!$C$2:$C$941,"LT",RawData!$F$2:$F$941,"Pass",RawData!$G$2:$G$941,"<>0"),0) | G2: =IFERROR(SQRT(SUMPRODUCT((RawData!$C$2:$C$941="LT")*(RawData!$F$2:$F$941="Pass")*(RawData!$G$2:$G$941<>0)*(RawData!$G$2:$G$941-$F2)^2)/($E2-1)),0) | H2: =IFERROR(AGGREGATE(15,6,RawData!$G$2:$G$941/((RawData!$C$2:$C$941="LT")*(RawData!$G$2:$G$941<>0)),1),0) | I2: =IFERROR(AGGREGATE(14,6,RawData!$G$2:$G$941/((RawData!$C$2:$C$941="LT")*(RawData!$G$2:$G$941<>0)),1),0) | J2: =IFERROR(($I2-$H2+$G2)/30,1) | K2: =$H2-0.5*$G2
A3: LT | B3: Evap Inlet Ret Bend A | C3: H | D3: =COUNTIFS(RawData!$C$2:$C$941,"LT",RawData!$H$2:$H$941,"<>0") | E3: =COUNTIFS(RawData!$C$2:$C$941,"LT",RawData!$F$2:$F$941,"Pass",RawData!$H$2:$H$941,"<>0") | F3: =IFERROR(AVERAGEIFS(RawData!$H$2:$H$941,RawData!$C$2:$C$941,"LT",RawData!$F$2:$F$941,"Pass",RawData!$H$2:$H$941,"<>0"),0) | G3: =IFERROR(SQRT(SUMPRODUCT((RawData!$C$2:$C$941="LT")*(RawData!$F$2:$F$941="Pass")*(RawData!$H$2:$H$941<>0)*(RawData!$H$2:$H$941-$F3)^2)/($E3-1)),0) | H3: =IFERROR(AGGREGATE(15,6,RawData!$H$2:$H$941/((RawData!$C$2:$C$941="LT")*(RawData!$H$2:$H$941<>0)),1),0) | I3: =IFERROR(AGGREGATE(14,6,RawData!$H$2:$H$941/((RawData!$C$2:$C$941="LT")*(RawData!$H$2:$H$941<>0)),1),0) | J3: =IFERROR(($I3-$H3+$G3)/30,1) | K3: =$H3-0.5*$G3
A4: LT | B4: Evap Inlet Ret Bend B | C4: I | D4: =COUNTIFS(RawData!$C$2:$C$941,"LT",RawData!$I$2:$I$941,"<>0") | E4: =COUNTIFS(RawData!$C$2:$C$941,"LT",RawData!$F$2:$F$941,"Pass",RawData!$I$2:$I$941,"<>0") | F4: =IFERROR(AVERAGEIFS(RawData!$I$2:$I$941,RawData!$C$2:$C$941,"LT",RawData!$F$2:$F$941,"Pass",RawData!$I$2:$I$941,"<>0"),0) | G4: =IFERROR(SQRT(SUMPRODUCT((RawData!$C$2:$C$941="LT")*(RawData!$F$2:$F$941="Pass")*(RawData!$I$2:$I$941<>0)*(RawData!$I$2:$I$941-$F4)^2)/($E4-1)),0) | H4: =IFERROR(AGGREGATE(15,6,RawData!$I$2:$I$941/((RawData!$C$2:$C$941="LT")*(RawData!$I$2:$I$941<>0)),1),0) | I4: =IFERROR(AGGREGATE(14,6,RawData!$I$2:$I$941/((RawData!$C$2:$C$941="LT")*(RawData!$I$2:$I$941<>0)),1),0) | J4: =IFERROR(($I4-$H4+$G4)/30,1) | K4: =$H4-0.5*$G4
A5: LT | B5: Evap Outlet Air Temp | C5: J | D5: =COUNTIFS(RawData!$C$2:$C$941,"LT",RawData!$J$2:$J$941,"<>0") | E5: =COUNTIFS(RawData!$C$2:$C$941,"LT",RawData!$F$2:$F$941,"Pass",RawData!$J$2:$J$941,"<>0") | F5: =IFERROR(AVERAGEIFS(RawData!$J$2:$J$941,RawData!$C$2:$C$941,"LT",RawData!$F$2:$F$941,"Pass",RawData!$J$2:$J$941,"<>0"),0) | G5: =IFERROR(SQRT(SUMPRODUCT((RawData!$C$2:$C$941="LT")*(RawData!$F$2:$F$941="Pass")*(RawData!$J$2:$J$941<>0)*(RawData!$J$2:$J$941-$F5)^2)/($E5-1)),0) | H5: =IFERROR(AGGREGATE(15,6,RawData!$J$2:$J$941/((RawData!$C$2:$C$941="LT")*(RawData!$J$2:$J$941<>0)),1),0) | I5: =IFERROR(AGGREGATE(14,6,RawData!$J$2:$J$941/((RawData!$C$2:$C$941="LT")*(RawData!$J$2:$J$941<>0)),1),0) | J5: =IFERROR(($I5-$H5+$G5)/30,1) | K5: =$H5-0.5*$G5
A6: LT | B6: Evap B Outlet Air Temp | C6: K | D6: =COUNTIFS(RawData!$C$2:$C$941,"LT",RawData!$K$2:$K$941,"<>0") | E6: =COUNTIFS(RawData!$C$2:$C$941,"LT",RawData!$F$2:$F$941,"Pass",RawData!$K$2:$K$941,"<>0") | F6: =IFERROR(AVERAGEIFS(RawData!$K$2:$K$941,RawData!$C$2:$C$941,"LT",RawData!$F$2:$F$941,"Pass",RawData!$K$2:$K$941,"<>0"),0) | G6: =IFERROR(SQRT(SUMPRODUCT((RawData!$C$2:$C$941="LT")*(RawData!$F$2:$F$941="Pass")*(RawData!$K$2:$K$941<>0)*(RawData!$K$2:$K$941-$F6)^2)/($E6-1)),0) | H6: =IFERROR(AGGREGATE(15,6,RawData!$K$2:$K$941/((RawData!$C$2:$C$941="LT")*(RawData!$K$2:$K$941<>0)),1),0) | I6: =IFERROR(AGGREGATE(14,6,RawData!$K$2:$K$941/((RawData!$C$2:$C$941="LT")*(RawData!$K$2:$K$941<>0)),1),0) | J6: =IFERROR(($I6-$H6+$G6)/30,1) | K6: =$H6-0.5*$G6
A7: LT | B7: Inlet/Outlet Delta | C7: L | D7: =COUNTIFS(RawData!$C$2:$C$941,"LT",RawData!$L$2:$L$941,"<>0") | E7: =COUNTIFS(RawData!$C$2:$C$941,"LT",RawData!$F$2:$F$941,"Pass",RawData!$L$2:$L$941,"<>0") | F7: =IFERROR(AVERAGEIFS(RawData!$L$2:$L$941,RawData!$C$2:$C$941,"LT",RawData!$F$2:$F$941,"Pass",RawData!$L$2:$L$941,"<>0"),0) | G7: =IFERROR(SQRT(SUMPRODUCT((RawData!$C$2:$C$941="LT")*(RawData!$F$2:$F$941="Pass")*(RawData!$L$2:$L$941<>0)*(RawData!$L$2:$L$941-$F7)^2)/($E7-1)),0) | H7: =IFERROR(AGGREGATE(15,6,RawData!$L$2:$L$941/((RawData!$C$2:$C$941="LT")*(RawData!$L$2:$L$941<>0)),1),0) | I7: =IFERROR(AGGREGATE(14,6,RawData!$L$2:$L$941/((RawData!$C$2:$C$941="LT")*(RawData!$L$2:$L$941<>0)),1),0) | J7: =IFERROR(($I7-$H7+$G7)/30,1) | K7: =$H7-0.5*$G7
A8: LT | B8: Inlet/Outlet B Delta | C8: M | D8: =COUNTIFS(RawData!$C$2:$C$941,"LT",RawData!$M$2:$M$941,"<>0") | E8: =COUNTIFS(RawData!$C$2:$C$941,"LT",RawData!$F$2:$F$941,"Pass",RawData!$M$2:$M$941,"<>0") | F8: =IFERROR(AVERAGEIFS(RawData!$M$2:$M$941,RawData!$C$2:$C$941,"LT",RawData!$F$2:$F$941,"Pass",RawData!$M$2:$M$941,"<>0"),0) | G8: =IFERROR(SQRT(SUMPRODUCT((RawData!$C$2:$C$941="LT")*(RawData!$F$2:$F$941="Pass")*(RawData!$M$2:$M$941<>0)*(RawData!$M$2:$M$941-$F8)^2)/($E8-1)),0) | H8: =IFERROR(AGGREGATE(15,6,RawData!$M$2:$M$941/((RawData!$C$2:$C$941="LT")*(RawData!$M$2:$M$941<>0)),1),0) | I8: =IFERROR(AGGREGATE(14,6,RawData!$M$2:$M$941/((RawData!$C$2:$C$941="LT")*(RawData!$M$2:$M$941<>0)),1),0) | J8: =IFERROR(($I8-$H8+$G8)/30,1) | K8: =$H8-0.5*$G8
A9: LT | B9: Ambient Temp | C9: N | D9: =COUNTIFS(RawData!$C$2:$C$941,"LT",RawData!$N$2:$N$941,"<>0") | E9: =COUNTIFS(RawData!$C$2:$C$941,"LT",RawData!$F$2:$F$941,"Pass",RawData!$N$2:$N$941,"<>0") | F9: =IFERROR(AVERAGEIFS(RawData!$N$2:$N$941,RawData!$C$2:$C$941,"LT",RawData!$F$2:$F$941,"Pass",RawData!$N$2:$N$941,"<>0"),0) | G9: =IFERROR(SQRT(SUMPRODUCT((RawData!$C$2:$C$941="LT")*(RawData!$F$2:$F$941="Pass")*(RawData!$N$2:$N$941<>0)*(RawData!$N$2:$N$941-$F9)^2)/($E9-1)),0) | H9: =IFERROR(AGGREGATE(15,6,RawData!$N$2:$N$941/((RawData!$C$2:$C$941="LT")*(RawData!$N$2:$N$941<>0)),1),0) | I9: =IFERROR(AGGREGATE(14,6,RawData!$N$2:$N$941/((RawData!$C$2:$C$941="LT")*(RawData!$N$2:$N$941<>0)),1),0) | J9: =IFERROR(($I9-$H9+$G9)/30,1) | K9: =$H9-0.5*$G9
A10: LT | B10: Startup Voltage | C10: O | D10: =COUNTIFS(RawData!$C$2:$C$941,"LT",RawData!$O$2:$O$941,"<>0") | E10: =COUNTIFS(RawData!$C$2:$C$941,"LT",RawData!$F$2:$F$941,"Pass",RawData!$O$2:$O$941,"<>0") | F10: =IFERROR(AVERAGEIFS(RawData!$O$2:$O$941,RawData!$C$2:$C$941,"LT",RawData!$F$2:$F$941,"Pass",RawData!$O$2:$O$941,"<>0"),0) | G10: =IFERROR(SQRT(SUMPRODUCT((RawData!$C$2:$C$941="LT")*(RawData!$F$2:$F$941="Pass")*(RawData!$O$2:$O$941<>0)*(RawData!$O$2:$O$941-$F10)^2)/($E10-1)),0) | H10: =IFERROR(AGGREGATE(15,6,RawData!$O$2:$O$941/((RawData!$C$2:$C$941="LT")*(RawData!$O$2:$O$941<>0)),1),0) | I10: =IFERROR(AGGREGATE(14,6,RawData!$O$2:$O$941/((RawData!$C$2:$C$941="LT")*(RawData!$O$2:$O$941<>0)),1),0) | J10: =IFERROR(($I10-$H10+$G10)/30,1) | K10: =$H10-0.5*$G10
A11: LT | B11: Final Voltage | C11: P | D11: =COUNTIFS(RawData!$C$2:$C$941,"LT",RawData!$P$2:$P$941,"<>0") | E11: =COUNTIFS(RawData!$C$2:$C$941,"LT",RawData!$F$2:$F$941,"Pass",RawData!$P$2:$P$941,"<>0") | F11: =IFERROR(AVERAGEIFS(RawData!$P$2:$P$941,RawData!$C$2:$C$941,"LT",RawData!$F$2:$F$941,"Pass",RawData!$P$2:$P$941,"<>0"),0) | G11: =IFERROR(SQRT(SUMPRODUCT((RawData!$C$2:$C$941="LT")*(RawData!$F$2:$F$941="Pass")*(RawData!$P$2:$P$941<>0)*(RawData!$P$2:$P$941-$F11)^2)/($E11-1)),0) | H11: =IFERROR(AGGREGATE(15,6,RawData!$P$2:$P$941/((RawData!$C$2:$C$941="LT")*(RawData!$P$2:$P$941<>0)),1),0) | I11: =IFERROR(AGGREGATE(14,6,RawData!$P$2:$P$941/((RawData!$C$2:$C$941="LT")*(RawData!$P$2:$P$941<>0)),1),0) | J11: =IFERROR(($I11-$H11+$G11)/30,1) | K11: =$H11-0.5*$G11
A12: LT | B12: Startup Current | C12: Q | D12: =COUNTIFS(RawData!$C$2:$C$941,"LT",RawData!$Q$2:$Q$941,"<>0") | E12: =COUNTIFS(RawData!$C$2:$C$941,"LT",RawData!$F$2:$F$941,"Pass",RawData!$Q$2:$Q$941,"<>0") | F12: =IFERROR(AVERAGEIFS(RawData!$Q$2:$Q$941,RawData!$C$2:$C$941,"LT",RawData!$F$2:$F$941,"Pass",RawData!$Q$2:$Q$941,"<>0"),0) | G12: =IFERROR(SQRT(SUMPRODUCT((RawData!$C$2:$C$941="LT")*(RawData!$F$2:$F$941="Pass")*(RawData!$Q$2:$Q$941<>0)*(RawData!$Q$2:$Q$941-$F12)^2)/($E12-1)),0) | H12: =IFERROR(AGGREGATE(15,6,RawData!$Q$2:$Q$941/((RawData!$C$2:$C$941="LT")*(RawData!$Q$2:$Q$941<>0)),1),0) | I12: =IFERROR(AGGREGATE(14,6,RawData!$Q$2:$Q$941/((RawData!$C$2:$C$941="LT")*(RawData!$Q$2:$Q$941<>0)),1),0) | J12: =IFERROR(($I12-$H12+$G12)/30,1) | K12: =$H12-0.5*$G12
A13: LT | B13: Final Current | C13: R | D13: =COUNTIFS(RawData!$C$2:$C$941,"LT",RawData!$R$2:$R$941,"<>0") | E13: =COUNTIFS(RawData!$C$2:$C$941,"LT",RawData!$F$2:$F$941,"Pass",RawData!$R$2:$R$941,"<>0") | F13: =IFERROR(AVERAGEIFS(RawData!$R$2:$R$941,RawData!$C$2:$C$941,"LT",RawData!$F$2:$F$941,"Pass",RawData!$R$2:$R$941,"<>0"),0) | G13: =IFERROR(SQRT(SUMPRODUCT((RawData!$C$2:$C$941="LT")*(RawData!$F$2:$F$941="Pass")*(RawData!$R$2:$R$941<>0)*(RawData!$R$2:$R$941-$F13)^2)/($E13-1)),0) | H13: =IFERROR(AGGREGATE(15,6,RawData!$R$2:$R$941/((RawData!$C$2:$C$941="LT")*(RawData!$R$2:$R$941<>0)),1),0) | I13: =IFERROR(AGGREGATE(14,6,RawData!$R$2:$R$941/((RawData!$C$2:$C$941="LT")*(RawData!$R$2:$R$941<>0)),1),0) | J13: =IFERROR(($I13-$H13+$G13)/30,1) | K13: =$H13-0.5*$G13
A14: MT | B14: Suction Tube Temp | C14: G | D14: =COUNTIFS(RawData!$C$2:$C$941,"MT",RawData!$G$2:$G$941,"<>0") | E14: =COUNTIFS(RawData!$C$2:$C$941,"MT",RawData!$F$2:$F$941,"Pass",RawData!$G$2:$G$941,"<>0") | F14: =IFERROR(AVERAGEIFS(RawData!$G$2:$G$941,RawData!$C$2:$C$941,"MT",RawData!$F$2:$F$941,"Pass",RawData!$G$2:$G$941,"<>0"),0) | G14: =IFERROR(SQRT(SUMPRODUCT((RawData!$C$2:$C$941="MT")*(RawData!$F$2:$F$941="Pass")*(RawData!$G$2:$G$941<>0)*(RawData!$G$2:$G$941-$F14)^2)/($E14-1)),0) | H14: =IFERROR(AGGREGATE(15,6,RawData!$G$2:$G$941/((RawData!$C$2:$C$941="MT")*(RawData!$G$2:$G$941<>0)),1),0) | I14: =IFERROR(AGGREGATE(14,6,RawData!$G$2:$G$941/((RawData!$C$2:$C$941="MT")*(RawData!$G$2:$G$941<>0)),1),0) | J14: =IFERROR(($I14-$H14+$G14)/30,1) | K14: =$H14-0.5*$G14
A15: MT | B15: Evap Inlet Ret Bend A | C15: H | D15: =COUNTIFS(RawData!$C$2:$C$941,"MT",RawData!$H$2:$H$941,"<>0") | E15: =COUNTIFS(RawData!$C$2:$C$941,"MT",RawData!$F$2:$F$941,"Pass",RawData!$H$2:$H$941,"<>0") | F15: =IFERROR(AVERAGEIFS(RawData!$H$2:$H$941,RawData!$C$2:$C$941,"MT",RawData!$F$2:$F$941,"Pass",RawData!$H$2:$H$941,"<>0"),0) | G15: =IFERROR(SQRT(SUMPRODUCT((RawData!$C$2:$C$941="MT")*(RawData!$F$2:$F$941="Pass")*(RawData!$H$2:$H$941<>0)*(RawData!$H$2:$H$941-$F15)^2)/($E15-1)),0) | H15: =IFERROR(AGGREGATE(15,6,RawData!$H$2:$H$941/((RawData!$C$2:$C$941="MT")*(RawData!$H$2:$H$941<>0)),1),0) | I15: =IFERROR(AGGREGATE(14,6,RawData!$H$2:$H$941/((RawData!$C$2:$C$941="MT")*(RawData!$H$2:$H$941<>0)),1),0) | J15: =IFERROR(($I15-$H15+$G15)/30,1) | K15: =$H15-0.5*$G15
A16: MT | B16: Evap Inlet Ret Bend B | C16: I | D16: =COUNTIFS(RawData!$C$2:$C$941,"MT",RawData!$I$2:$I$941,"<>0") | E16: =COUNTIFS(RawData!$C$2:$C$941,"MT",RawData!$F$2:$F$941,"Pass",RawData!$I$2:$I$941,"<>0") | F16: =IFERROR(AVERAGEIFS(RawData!$I$2:$I$941,RawData!$C$2:$C$941,"MT",RawData!$F$2:$F$941,"Pass",RawData!$I$2:$I$941,"<>0"),0) | G16: =IFERROR(SQRT(SUMPRODUCT((RawData!$C$2:$C$941="MT")*(RawData!$F$2:$F$941="Pass")*(RawData!$I$2:$I$941<>0)*(RawData!$I$2:$I$941-$F16)^2)/($E16-1)),0) | H16: =IFERROR(AGGREGATE(15,6,RawData!$I$2:$I$941/((RawData!$C$2:$C$941="MT")*(RawData!$I$2:$I$941<>0)),1),0) | I16: =IFERROR(AGGREGATE(14,6,RawData!$I$2:$I$941/((RawData!$C$2:$C$941="MT")*(RawData!$I$2:$I$941<>0)),1),0) | J16: =IFERROR(($I16-$H16+$G16)/30,1) | K16: =$H16-0.5*$G16
A17: MT | B17: Evap Outlet Air Temp | C17: J | D17: =COUNTIFS(RawData!$C$2:$C$941,"MT",RawData!$J$2:$J$941,"<>0") | E17: =COUNTIFS(RawData!$C$2:$C$941,"MT",RawData!$F$2:$F$941,"Pass",RawData!$J$2:$J$941,"<>0") | F17: =IFERROR(AVERAGEIFS(RawData!$J$2:$J$941,RawData!$C$2:$C$941,"MT",RawData!$F$2:$F$941,"Pass",RawData!$J$2:$J$941,"<>0"),0) | G17: =IFERROR(SQRT(SUMPRODUCT((RawData!$C$2:$C$941="MT")*(RawData!$F$2:$F$941="Pass")*(RawData!$J$2:$J$941<>0)*(RawData!$J$2:$J$941-$F17)^2)/($E17-1)),0) | H17: =IFERROR(AGGREGATE(15,6,RawData!$J$2:$J$941/((RawData!$C$2:$C$941="MT")*(RawData!$J$2:$J$941<>0)),1),0) | I17: =IFERROR(AGGREGATE(14,6,RawData!$J$2:$J$941/((RawData!$C$2:$C$941="MT")*(RawData!$J$2:$J$941<>0)),1),0) | J17: =IFERROR(($I17-$H17+$G17)/30,1) | K17: =$H17-0.5*$G17
A18: MT | B18: Evap B Outlet Air Temp | C18: K | D18: =COUNTIFS(RawData!$C$2:$C$941,"MT",RawData!$K$2:$K$941,"<>0") | E18: =COUNTIFS(RawData!$C$2:$C$941,"MT",RawData!$F$2:$F$941,"Pass",RawData!$K$2:$K$941,"<>0") | F18: =IFERROR(AVERAGEIFS(RawData!$K$2:$K$941,RawData!$C$2:$C$941,"MT",RawData!$F$2:$F$941,"Pass",RawData!$K$2:$K$941,"<>0"),0) | G18: =IFERROR(SQRT(SUMPRODUCT((RawData!$C$2:$C$941="MT")*(RawData!$F$2:$F$941="Pass")*(RawData!$K$2:$K$941<>0)*(RawData!$K$2:$K$941-$F18)^2)/($E18-1)),0) | H18: =IFERROR(AGGREGATE(15,6,RawData!$K$2:$K$941/((RawData!$C$2:$C$941="MT")*(RawData!$K$2:$K$941<>0)),1),0) | I18: =IFERROR(AGGREGATE(14,6,RawData!$K$2:$K$941/((RawData!$C$2:$C$941="MT")*(RawData!$K$2:$K$941<>0)),1),0) | J18: =IFERROR(($I18-$H18+$G18)/30,1) | K18: =$H18-0.5*$G18
A19: MT | B19: Inlet/Outlet Delta | C19: L | D19: =COUNTIFS(RawData!$C$2:$C$941,"MT",RawData!$L$2:$L$941,"<>0") | E19: =COUNTIFS(RawData!$C$2:$C$941,"MT",RawData!$F$2:$F$941,"Pass",RawData!$L$2:$L$941,"<>0") | F19: =IFERROR(AVERAGEIFS(RawData!$L$2:$L$941,RawData!$C$2:$C$941,"MT",RawData!$F$2:$F$941,"Pass",RawData!$L$2:$L$941,"<>0"),0) | G19: =IFERROR(SQRT(SUMPRODUCT((RawData!$C$2:$C$941="MT")*(RawData!$F$2:$F$941="Pass")*(RawData!$L$2:$L$941<>0)*(RawData!$L$2:$L$941-$F19)^2)/($E19-1)),0) | H19: =IFERROR(AGGREGATE(15,6,RawData!$L$2:$L$941/((RawData!$C$2:$C$941="MT")*(RawData!$L$2:$L$941<>0)),1),0) | I19: =IFERROR(AGGREGATE(14,6,RawData!$L$2:$L$941/((RawData!$C$2:$C$941="MT")*(RawData!$L$2:$L$941<>0)),1),0) | J19: =IFERROR(($I19-$H19+$G19)/30,1) | K19: =$H19-0.5*$G19
A20: MT | B20: Inlet/Outlet B Delta | C20: M | D20: =COUNTIFS(RawData!$C$2:$C$941,"MT",RawData!$M$2:$M$941,"<>0") | E20: =COUNTIFS(RawData!$C$2:$C$941,"MT",RawData!$F$2:$F$941,"Pass",RawData!$M$2:$M$941,"<>0") | F20: =IFERROR(AVERAGEIFS(RawData!$M$2:$M$941,RawData!$C$2:$C$941,"MT",RawData!$F$2:$F$941,"Pass",RawData!$M$2:$M$941,"<>0"),0) | G20: =IFERROR(SQRT(SUMPRODUCT((RawData!$C$2:$C$941="MT")*(RawData!$F$2:$F$941="Pass")*(RawData!$M$2:$M$941<>0)*(RawData!$M$2:$M$941-$F20)^2)/($E20-1)),0) | H20: =IFERROR(AGGREGATE(15,6,RawData!$M$2:$M$941/((RawData!$C$2:$C$941="MT")*(RawData!$M$2:$M$941<>0)),1),0) | I20: =IFERROR(AGGREGATE(14,6,RawData!$M$2:$M$941/((RawData!$C$2:$C$941="MT")*(RawData!$M$2:$M$941<>0)),1),0) | J20: =IFERROR(($I20-$H20+$G20)/30,1) | K20: =$H20-0.5*$G20
A21: MT | B21: Ambient Temp | C21: N | D21: =COUNTIFS(RawData!$C$2:$C$941,"MT",RawData!$N$2:$N$941,"<>0") | E21: =COUNTIFS(RawData!$C$2:$C$941,"MT",RawData!$F$2:$F$941,"Pass",RawData!$N$2:$N$941,"<>0") | F21: =IFERROR(AVERAGEIFS(RawData!$N$2:$N$941,RawData!$C$2:$C$941,"MT",RawData!$F$2:$F$941,"Pass",RawData!$N$2:$N$941,"<>0"),0) | G21: =IFERROR(SQRT(SUMPRODUCT((RawData!$C$2:$C$941="MT")*(RawData!$F$2:$F$941="Pass")*(RawData!$N$2:$N$941<>0)*(RawData!$N$2:$N$941-$F21)^2)/($E21-1)),0) | H21: =IFERROR(AGGREGATE(15,6,RawData!$N$2:$N$941/((RawData!$C$2:$C$941="MT")*(RawData!$N$2:$N$941<>0)),1),0) | I21: =IFERROR(AGGREGATE(14,6,RawData!$N$2:$N$941/((RawData!$C$2:$C$941="MT")*(RawData!$N$2:$N$941<>0)),1),0) | J21: =IFERROR(($I21-$H21+$G21)/30,1) | K21: =$H21-0.5*$G21
A22: MT | B22: Startup Voltage | C22: O | D22: =COUNTIFS(RawData!$C$2:$C$941,"MT",RawData!$O$2:$O$941,"<>0") | E22: =COUNTIFS(RawData!$C$2:$C$941,"MT",RawData!$F$2:$F$941,"Pass",RawData!$O$2:$O$941,"<>0") | F22: =IFERROR(AVERAGEIFS(RawData!$O$2:$O$941,RawData!$C$2:$C$941,"MT",RawData!$F$2:$F$941,"Pass",RawData!$O$2:$O$941,"<>0"),0) | G22: =IFERROR(SQRT(SUMPRODUCT((RawData!$C$2:$C$941="MT")*(RawData!$F$2:$F$941="Pass")*(RawData!$O$2:$O$941<>0)*(RawData!$O$2:$O$941-$F22)^2)/($E22-1)),0) | H22: =IFERROR(AGGREGATE(15,6,RawData!$O$2:$O$941/((RawData!$C$2:$C$941="MT")*(RawData!$O$2:$O$941<>0)),1),0) | I22: =IFERROR(AGGREGATE(14,6,RawData!$O$2:$O$941/((RawData!$C$2:$C$941="MT")*(RawData!$O$2:$O$941<>0)),1),0) | J22: =IFERROR(($I22-$H22+$G22)/30,1) | K22: =$H22-0.5*$G22
A23: MT | B23: Final Voltage | C23: P | D23: =COUNTIFS(RawData!$C$2:$C$941,"MT",RawData!$P$2:$P$941,"<>0") | E23: =COUNTIFS(RawData!$C$2:$C$941,"MT",RawData!$F$2:$F$941,"Pass",RawData!$P$2:$P$941,"<>0") | F23: =IFERROR(AVERAGEIFS(RawData!$P$2:$P$941,RawData!$C$2:$C$941,"MT",RawData!$F$2:$F$941,"Pass",RawData!$P$2:$P$941,"<>0"),0) | G23: =IFERROR(SQRT(SUMPRODUCT((RawData!$C$2:$C$941="MT")*(RawData!$F$2:$F$941="Pass")*(RawData!$P$2:$P$941<>0)*(RawData!$P$2:$P$941-$F23)^2)/($E23-1)),0) | H23: =IFERROR(AGGREGATE(15,6,RawData!$P$2:$P$941/((RawData!$C$2:$C$941="MT")*(RawData!$P$2:$P$941<>0)),1),0) | I23: =IFERROR(AGGREGATE(14,6,RawData!$P$2:$P$941/((RawData!$C$2:$C$941="MT")*(RawData!$P$2:$P$941<>0)),1),0) | J23: =IFERROR(($I23-$H23+$G23)/30,1) | K23: =$H23-0.5*$G23
A24: MT | B24: Startup Current | C24: Q | D24: =COUNTIFS(RawData!$C$2:$C$941,"MT",RawData!$Q$2:$Q$941,"<>0") | E24: =COUNTIFS(RawData!$C$2:$C$941,"MT",RawData!$F$2:$F$941,"Pass",RawData!$Q$2:$Q$941,"<>0") | F24: =IFERROR(AVERAGEIFS(RawData!$Q$2:$Q$941,RawData!$C$2:$C$941,"MT",RawData!$F$2:$F$941,"Pass",RawData!$Q$2:$Q$941,"<>0"),0) | G24: =IFERROR(SQRT(SUMPRODUCT((RawData!$C$2:$C$941="MT")*(RawData!$F$2:$F$941="Pass")*(RawData!$Q$2:$Q$941<>0)*(RawData!$Q$2:$Q$941-$F24)^2)/($E24-1)),0) | H24: =IFERROR(AGGREGATE(15,6,RawData!$Q$2:$Q$941/((RawData!$C$2:$C$941="MT")*(RawData!$Q$2:$Q$941<>0)),1),0) | I24: =IFERROR(AGGREGATE(14,6,RawData!$Q$2:$Q$941/((RawData!$C$2:$C$941="MT")*(RawData!$Q$2:$Q$941<>0)),1),0) | J24: =IFERROR(($I24-$H24+$G24)/30,1) | K24: =$H24-0.5*$G24
A25: MT | B25: Final Current | C25: R | D25: =COUNTIFS(RawData!$C$2:$C$941,"MT",RawData!$R$2:$R$941,"<>0") | E25: =COUNTIFS(RawData!$C$2:$C$941,"MT",RawData!$F$2:$F$941,"Pass",RawData!$R$2:$R$941,"<>0") | F25: =IFERROR(AVERAGEIFS(RawData!$R$2:$R$941,RawData!$C$2:$C$941,"MT",RawData!$F$2:$F$941,"Pass",RawData!$R$2:$R$941,"<>0"),0) | G25: =IFERROR(SQRT(SUMPRODUCT((RawData!$C$2:$C$941="MT")*(RawData!$F$2:$F$941="Pass")*(RawData!$R$2:$R$941<>0)*(RawData!$R$2:$R$941-$F25)^2)/($E25-1)),0) | H25: =IFERROR(AGGREGATE(15,6,RawData!$R$2:$R$941/((RawData!$C$2:$C$941="MT")*(RawData!$R$2:$R$941<>0)),1),0) | I25: =IFERROR(AGGREGATE(14,6,RawData!$R$2:$R$941/((RawData!$C$2:$C$941="MT")*(RawData!$R$2:$R$941<>0)),1),0) | J25: =IFERROR(($I25-$H25+$G25)/30,1) | K25: =$H25-0.5*$G25

Sheet LT_HistData
A1: BinCenter | B1: BinLo | C1: BinHi | D1: TotalCount | E1: Normal | F1: Warning(2-3s) | G1: Outlier(>3s) | H1: CurveY
A2: =Config!$K$2+0*Config!$J$2+Config!$J$2/2 | B2: =$A2-Config!$J$2/2 | C2: =$A2+Config!$J$2/2 | D2: =COUNTIFS(RawData!$C$2:$C$941,"LT",RawData!$G$2:$G$941,">="&$B2,RawData!$G$2:$G$941,"<"&$C2,RawData!$G$2:$G$941,"<>0") | E2: =IF(Config!$G$2=0,0,IF(ABS(($A2-Config!$F$2)/Config!$G$2)<=2,$D2,0)) | F2: =IF(Config!$G$2=0,0,IF(AND(ABS(($A2-Config!$F$2)/Config!$G$2)>2,ABS(($A2-Config!$F$2)/Config!$G$2)<=3),$D2,0)) | G2: =IF(Config!$G$2=0,0,IF(ABS(($A2-Config!$F$2)/Config!$G$2)>3,$D2,0)) | H2: =IFERROR(NORM.DIST($A2,Config!$F$2,Config!$G$2,FALSE)*Config!$D$2*Config!$J$2,0)
A3: =Config!$K$2+1*Config!$J$2+Config!$J$2/2 | B3: =$A3-Config!$J$2/2 | C3: =$A3+Config!$J$2/2 | D3: =COUNTIFS(RawData!$C$2:$C$941,"LT",RawData!$G$2:$G$941,">="&$B3,RawData!$G$2:$G$941,"<"&$C3,RawData!$G$2:$G$941,"<>0") | E3: =IF(Config!$G$2=0,0,IF(ABS(($A3-Config!$F$2)/Config!$G$2)<=2,$D3,0)) | F3: =IF(Config!$G$2=0,0,IF(AND(ABS(($A3-Config!$F$2)/Config!$G$2)>2,ABS(($A3-Config!$F$2)/Config!$G$2)<=3),$D3,0)) | G3: =IF(Config!$G$2=0,0,IF(ABS(($A3-Config!$F$2)/Config!$G$2)>3,$D3,0)) | H3: =IFERROR(NORM.DIST($A3,Config!$F$2,Config!$G$2,FALSE)*Config!$D$2*Config!$J$2,0)
A4: =Config!$K$2+2*Config!$J$2+Config!$J$2/2 | B4: =$A4-Config!$J$2/2 | C4: =$A4+Config!$J$2/2 | D4: =COUNTIFS(RawData!$C$2:$C$941,"LT",RawData!$G$2:$G$941,">="&$B4,RawData!$G$2:$G$941,"<"&$C4,RawData!$G$2:$G$941,"<>0") | E4: =IF(Config!$G$2=0,0,IF(ABS(($A4-Config!$F$2)/Config!$G$2)<=2,$D4,0)) | F4: =IF(Config!$G$2=0,0,IF(AND(ABS(($A4-Config!$F$2)/Config!$G$2)>2,ABS(($A4-Config!$F$2)/Config!$G$2)<=3),$D4,0)) | G4: =IF(Config!$G$2=0,0,IF(ABS(($A4-Config!$F$2)/Config!$G$2)>3,$D4,0)) | H4: =IFERROR(NORM.DIST($A4,Config!$F$2,Config!$G$2,FALSE)*Config!$D$2*Config!$J$2,0)
A5: =Config!$K$2+3*Config!$J$2+Config!$J$2/2 | B5: =$A5-Config!$J$2/2 | C5: =$A5+Config!$J$2/2 | D5: =COUNTIFS(RawData!$C$2:$C$941,"LT",RawData!$G$2:$G$941,">="&$B5,RawData!$G$2:$G$941,"<"&$C5,RawData!$G$2:$G$941,"<>0") | E5: =IF(Config!$G$2=0,0,IF(ABS(($A5-Config!$F$2)/Config!$G$2)<=2,$D5,0)) | F5: =IF(Config!$G$2=0,0,IF(AND(ABS(($A5-Config!$F$2)/Config!$G$2)>2,ABS(($A5-Config!$F$2)/Config!$G$2)<=3),$D5,0)) | G5: =IF(Config!$G$2=0,0,IF(ABS(($A5-Config!$F$2)/Config!$G$2)>3,$D5,0)) | H5: =IFERROR(NORM.DIST($A5,Config!$F$2,Config!$G$2,FALSE)*Config!$D$2*Config!$J$2,0)
A6: =Config!$K$2+4*Config!$J$2+Config!$J$2/2 | B6: =$A6-Config!$J$2/2 | C6: =$A6+Config!$J$2/2 | D6: =COUNTIFS(RawData!$C$2:$C$941,"LT",RawData!$G$2:$G$941,">="&$B6,RawData!$G$2:$G$941,"<"&$C6,RawData!$G$2:$G$941,"<>0") | E6: =IF(Config!$G$2=0,0,IF(ABS(($A6-Config!$F$2)/Config!$G$2)<=2,$D6,0)) | F6: =IF(Config!$G$2=0,0,IF(AND(ABS(($A6-Config!$F$2)/Config!$G$2)>2,ABS(($A6-Config!$F$2)/Config!$G$2)<=3),$D6,0)) | G6: =IF(Config!$G$2=0,0,IF(ABS(($A6-Config!$F$2)/Config!$G$2)>3,$D6,0)) | H6: =IFERROR(NORM.DIST($A6,Config!$F$2,Config!$G$2,FALSE)*Config!$D$2*Config!$J$2,0)
A7: =Config!$K$2+5*Config!$J$2+Config!$J$2/2 | B7: =$A7-Config!$J$2/2 | C7: =$A7+Config!$J$2/2 | D7: =COUNTIFS(RawData!$C$2:$C$941,"LT",RawData!$G$2:$G$941,">="&$B7,RawData!$G$2:$G$941,"<"&$C7,RawData!$G$2:$G$941,"<>0") | E7: =IF(Config!$G$2=0,0,IF(ABS(($A7-Config!$F$2)/Config!$G$2)<=2,$D7,0)) | F7: =IF(Config!$G$2=0,0,IF(AND(ABS(($A7-Config!$F$2)/Config!$G$2)>2,ABS(($A7-Config!$F$2)/Config!$G$2)<=3),$D7,0)) | G7: =IF(Config!$G$2=0,0,IF(ABS(($A7-Config!$F$2)/Config!$G$2)>3,$D7,0)) | H7: =IFERROR(NORM.DIST($A7,Config!$F$2,Config!$G$2,FALSE)*Config!$D$2*Config!$J$2,0)
A8: =Config!$K$2+6*Config!$J$2+Config!$J$2/2 | B8: =$A8-Config!$J$2/2 | C8: =$A8+Config!$J$2/2 | D8: =COUNTIFS(RawData!$C$2:$C$941,"LT",RawData!$G$2:$G$941,">="&$B8,RawData!$G$2:$G$941,"<"&$C8,RawData!$G$2:$G$941,"<>0") | E8: =IF(Config!$G$2=0,0,IF(ABS(($A8-Config!$F$2)/Config!$G$2)<=2,$D8,0)) | F8: =IF(Config!$G$2=0,0,IF(AND(ABS(($A8-Config!$F$2)/Config!$G$2)>2,ABS(($A8-Config!$F$2)/Config!$G$2)<=3),$D8,0)) | G8: =IF(Config!$G$2=0,0,IF(ABS(($A8-Config!$F$2)/Config!$G$2)>3,$D8,0)) | H8: =IFERROR(NORM.DIST($A8,Config!$F$2,Config!$G$2,FALSE)*Config!$D$2*Config!$J$2,0)
A9: =Config!$K$2+7*Config!$J$2+Config!$J$2/2 | B9: =$A9-Config!$J$2/2 | C9: =$A9+Config!$J$2/2 | D9: =COUNTIFS(RawData!$C$2:$C$941,"LT",RawData!$G$2:$G$941,">="&$B9,RawData!$G$2:$G$941,"<"&$C9,RawData!$G$2:$G$941,"<>0") | E9: =IF(Config!$G$2=0,0,IF(ABS(($A9-Config!$F$2)/Config!$G$2)<=2,$D9,0)) | F9: =IF(Config!$G$2=0,0,IF(AND(ABS(($A9-Config!$F$2)/Config!$G$2)>2,ABS(($A9-Config!$F$2)/Config!$G$2)<=3),$D9,0)) | G9: =IF(Config!$G$2=0,0,IF(ABS(($A9-Config!$F$2)/Config!$G$2)>3,$D9,0)) | H9: =IFERROR(NORM.DIST($A9,Config!$F$2,Config!$G$2,FALSE)*Config!$D$2*Config!$J$2,0)
A10: =Config!$K$2+8*Config!$J$2+Config!$J$2/2 | B10: =$A10-Config!$J$2/2 | C10: =$A10+Config!$J$2/2 | D10: =COUNTIFS(RawData!$C$2:$C$941,"LT",RawData!$G$2:$G$941,">="&$B10,RawData!$G$2:$G$941,"<"&$C10,RawData!$G$2:$G$941,"<>0") | E10: =IF(Config!$G$2=0,0,IF(ABS(($A10-Config!$F$2)/Config!$G$2)<=2,$D10,0)) | F10: =IF(Config!$G$2=0,0,IF(AND(ABS(($A10-Config!$F$2)/Config!$G$2)>2,ABS(($A10-Config!$F$2)/Config!$G$2)<=3),$D10,0)) | G10: =IF(Config!$G$2=0,0,IF(ABS(($A10-Config!$F$2)/Config!$G$2)>3,$D10,0)) | H10: =IFERROR(NORM.DIST($A10,Config!$F$2,Config!$G$2,FALSE)*Config!$D$2*Config!$J$2,0)
A11: =Config!$K$2+9*Config!$J$2+Config!$J$2/2 | B11: =$A11-Config!$J$2/2 | C11: =$A11+Config!$J$2/2 | D11: =COUNTIFS(RawData!$C$2:$C$941,"LT",RawData!$G$2:$G$941,">="&$B11,RawData!$G$2:$G$941,"<"&$C11,RawData!$G$2:$G$941,"<>0") | E11: =IF(Config!$G$2=0,0,IF(ABS(($A11-Config!$F$2)/Config!$G$2)<=2,$D11,0)) | F11: =IF(Config!$G$2=0,0,IF(AND(ABS(($A11-Config!$F$2)/Config!$G$2)>2,ABS(($A11-Config!$F$2)/Config!$G$2)<=3),$D11,0)) | G11: =IF(Config!$G$2=0,0,IF(ABS(($A11-Config!$F$2)/Config!$G$2)>3,$D11,0)) | H11: =IFERROR(NORM.DIST($A11,Config!$F$2,Config!$G$2,FALSE)*Config!$D$2*Config!$J$2,0)
A12: =Config!$K$2+10*Config!$J$2+Config!$J$2/2 | B12: =$A12-Config!$J$2/2 | C12: =$A12+Config!$J$2/2 | D12: =COUNTIFS(RawData!$C$2:$C$941,"LT",RawData!$G$2:$G$941,">="&$B12,RawData!$G$2:$G$941,"<"&$C12,RawData!$G$2:$G$941,"<>0") | E12: =IF(Config!$G$2=0,0,IF(ABS(($A12-Config!$F$2)/Config!$G$2)<=2,$D12,0)) | F12: =IF(Config!$G$2=0,0,IF(AND(ABS(($A12-Config!$F$2)/Config!$G$2)>2,ABS(($A12-Config!$F$2)/Config!$G$2)<=3),$D12,0)) | G12: =IF(Config!$G$2=0,0,IF(ABS(($A12-Config!$F$2)/Config!$G$2)>3,$D12,0)) | H12: =IFERROR(NORM.DIST($A12,Config!$F$2,Config!$G$2,FALSE)*Config!$D$2*Config!$J$2,0)
A13: =Config!$K$2+11*Config!$J$2+Config!$J$2/2 | B13: =$A13-Config!$J$2/2 | C13: =$A13+Config!$J$2/2 | D13: =COUNTIFS(RawData!$C$2:$C$941,"LT",RawData!$G$2:$G$941,">="&$B13,RawData!$G$2:$G$941,"<"&$C13,RawData!$G$2:$G$941,"<>0") | E13: =IF(Config!$G$2=0,0,IF(ABS(($A13-Config!$F$2)/Config!$G$2)<=2,$D13,0)) | F13: =IF(Config!$G$2=0,0,IF(AND(ABS(($A13-Config!$F$2)/Config!$G$2)>2,ABS(($A13-Config!$F$2)/Config!$G$2)<=3),$D13,0)) | G13: =IF(Config!$G$2=0,0,IF(ABS(($A13-Config!$F$2)/Config!$G$2)>3,$D13,0)) | H13: =IFERROR(NORM.DIST($A13,Config!$F$2,Config!$G$2,FALSE)*Config!$D$2*Config!$J$2,0)
A14: =Config!$K$2+12*Config!$J$2+Config!$J$2/2 | B14: =$A14-Config!$J$2/2 | C14: =$A14+Config!$J$2/2 | D14: =COUNTIFS(RawData!$C$2:$C$941,"LT",RawData!$G$2:$G$941,">="&$B14,RawData!$G$2:$G$941,"<"&$C14,RawData!$G$2:$G$941,"<>0") | E14: =IF(Config!$G$2=0,0,IF(ABS(($A14-Config!$F$2)/Config!$G$2)<=2,$D14,0)) | F14: =IF(Config!$G$2=0,0,IF(AND(ABS(($A14-Config!$F$2)/Config!$G$2)>2,ABS(($A14-Config!$F$2)/Config!$G$2)<=3),$D14,0)) | G14: =IF(Config!$G$2=0,0,IF(ABS(($A14-Config!$F$2)/Config!$G$2)>3,$D14,0)) | H14: =IFERROR(NORM.DIST($A14,Config!$F$2,Config!$G$2,FALSE)*Config!$D$2*Config!$J$2,0)
A15: =Config!$K$2+13*Config!$J$2+Config!$J$2/2 | B15: =$A15-Config!$J$2/2 | C15: =$A15+Config!$J$2/2 | D15: =COUNTIFS(RawData!$C$2:$C$941,"LT",RawData!$G$2:$G$941,">="&$B15,RawData!$G$2:$G$941,"<"&$C15,RawData!$G$2:$G$941,"<>0") | E15: =IF(Config!$G$2=0,0,IF(ABS(($A15-Config!$F$2)/Config!$G$2)<=2,$D15,0)) | F15: =IF(Config!$G$2=0,0,IF(AND(ABS(($A15-Config!$F$2)/Config!$G$2)>2,ABS(($A15-Config!$F$2)/Config!$G$2)<=3),$D15,0)) | G15: =IF(Config!$G$2=0,0,IF(ABS(($A15-Config!$F$2)/Config!$G$2)>3,$D15,0)) | H15: =IFERROR(NORM.DIST($A15,Config!$F$2,Config!$G$2,FALSE)*Config!$D$2*Config!$J$2,0)
A16: =Config!$K$2+14*Config!$J$2+Config!$J$2/2 | B16: =$A16-Config!$J$2/2 | C16: =$A16+Config!$J$2/2 | D16: =COUNTIFS(RawData!$C$2:$C$941,"LT",RawData!$G$2:$G$941,">="&$B16,RawData!$G$2:$G$941,"<"&$C16,RawData!$G$2:$G$941,"<>0") | E16: =IF(Config!$G$2=0,0,IF(ABS(($A16-Config!$F$2)/Config!$G$2)<=2,$D16,0)) | F16: =IF(Config!$G$2=0,0,IF(AND(ABS(($A16-Config!$F$2)/Config!$G$2)>2,ABS(($A16-Config!$F$2)/Config!$G$2)<=3),$D16,0)) | G16: =IF(Config!$G$2=0,0,IF(ABS(($A16-Config!$F$2)/Config!$G$2)>3,$D16,0)) | H16: =IFERROR(NORM.DIST($A16,Config!$F$2,Config!$G$2,FALSE)*Config!$D$2*Config!$J$2,0)
A17: =Config!$K$2+15*Config!$J$2+Config!$J$2/2 | B17: =$A17-Config!$J$2/2 | C17: =$A17+Config!$J$2/2 | D17: =COUNTIFS(RawData!$C$2:$C$941,"LT",RawData!$G$2:$G$941,">="&$B17,RawData!$G$2:$G$941,"<"&$C17,RawData!$G$2:$G$941,"<>0") | E17: =IF(Config!$G$2=0,0,IF(ABS(($A17-Config!$F$2)/Config!$G$2)<=2,$D17,0)) | F17: =IF(Config!$G$2=0,0,IF(AND(ABS(($A17-Config!$F$2)/Config!$G$2)>2,ABS(($A17-Config!$F$2)/Config!$G$2)<=3),$D17,0)) | G17: =IF(Config!$G$2=0,0,IF(ABS(($A17-Config!$F$2)/Config!$G$2)>3,$D17,0)) | H17: =IFERROR(NORM.DIST($A17,Config!$F$2,Config!$G$2,FALSE)*Config!$D$2*Config!$J$2,0)
A18: =Config!$K$2+16*Config!$J$2+Config!$J$2/2 | B18: =$A18-Config!$J$2/2 | C18: =$A18+Config!$J$2/2 | D18: =COUNTIFS(RawData!$C$2:$C$941,"LT",RawData!$G$2:$G$941,">="&$B18,RawData!$G$2:$G$941,"<"&$C18,RawData!$G$2:$G$941,"<>0") | E18: =IF(Config!$G$2=0,0,IF(ABS(($A18-Config!$F$2)/Config!$G$2)<=2,$D18,0)) | F18: =IF(Config!$G$2=0,0,IF(AND(ABS(($A18-Config!$F$2)/Config!$G$2)>2,ABS(($A18-Config!$F$2)/Config!$G$2)<=3),$D18,0)) | G18: =IF(Config!$G$2=0,0,IF(ABS(($A18-Config!$F$2)/Config!$G$2)>3,$D18,0)) | H18: =IFERROR(NORM.DIST($A18,Config!$F$2,Config!$G$2,FALSE)*Config!$D$2*Config!$J$2,0)
A19: =Config!$K$2+17*Config!$J$2+Config!$J$2/2 | B19: =$A19-Config!$J$2/2 | C19: =$A19+Config!$J$2/2 | D19: =COUNTIFS(RawData!$C$2:$C$941,"LT",RawData!$G$2:$G$941,">="&$B19,RawData!$G$2:$G$941,"<"&$C19,RawData!$G$2:$G$941,"<>0") | E19: =IF(Config!$G$2=0,0,IF(ABS(($A19-Config!$F$2)/Config!$G$2)<=2,$D19,0)) | F19: =IF(Config!$G$2=0,0,IF(AND(ABS(($A19-Config!$F$2)/Config!$G$2)>2,ABS(($A19-Config!$F$2)/Config!$G$2)<=3),$D19,0)) | G19: =IF(Config!$G$2=0,0,IF(ABS(($A19-Config!$F$2)/Config!$G$2)>3,$D19,0)) | H19: =IFERROR(NORM.DIST($A19,Config!$F$2,Config!$G$2,FALSE)*Config!$D$2*Config!$J$2,0)
A20: =Config!$K$2+18*Config!$J$2+Config!$J$2/2 | B20: =$A20-Config!$J$2/2 | C20: =$A20+Config!$J$2/2 | D20: =COUNTIFS(RawData!$C$2:$C$941,"LT",RawData!$G$2:$G$941,">="&$B20,RawData!$G$2:$G$941,"<"&$C20,RawData!$G$2:$G$941,"<>0") | E20: =IF(Config!$G$2=0,0,IF(ABS(($A20-Config!$F$2)/Config!$G$2)<=2,$D20,0)) | F20: =IF(Config!$G$2=0,0,IF(AND(ABS(($A20-Config!$F$2)/Config!$G$2)>2,ABS(($A20-Config!$F$2)/Config!$G$2)<=3),$D20,0)) | G20: =IF(Config!$G$2=0,0,IF(ABS(($A20-Config!$F$2)/Config!$G$2)>3,$D20,0)) | H20: =IFERROR(NORM.DIST($A20,Config!$F$2,Config!$G$2,FALSE)*Config!$D$2*Config!$J$2,0)
A21: =Config!$K$2+19*Config!$J$2+Config!$J$2/2 | B21: =$A21-Config!$J$2/2 | C21: =$A21+Config!$J$2/2 | D21: =COUNTIFS(RawData!$C$2:$C$941,"LT",RawData!$G$2:$G$941,">="&$B21,RawData!$G$2:$G$941,"<"&$C21,RawData!$G$2:$G$941,"<>0") | E21: =IF(Config!$G$2=0,0,IF(ABS(($A21-Config!$F$2)/Config!$G$2)<=2,$D21,0)) | F21: =IF(Config!$G$2=0,0,IF(AND(ABS(($A21-Config!$F$2)/Config!$G$2)>2,ABS(($A21-Config!$F$2)/Config!$G$2)<=3),$D21,0)) | G21: =IF(Config!$G$2=0,0,IF(ABS(($A21-Config!$F$2)/Config!$G$2)>3,$D21,0)) | H21: =IFERROR(NORM.DIST($A21,Config!$F$2,Config!$G$2,FALSE)*Config!$D$2*Config!$J$2,0)
A22: =Config!$K$2+20*Config!$J$2+Config!$J$2/2 | B22: =$A22-Config!$J$2/2 | C22: =$A22+Config!$J$2/2 | D22: =COUNTIFS(RawData!$C$2:$C$941,"LT",RawData!$G$2:$G$941,">="&$B22,RawData!$G$2:$G$941,"<"&$C22,RawData!$G$2:$G$941,"<>0") | E22: =IF(Config!$G$2=0,0,IF(ABS(($A22-Config!$F$2)/Config!$G$2)<=2,$D22,0)) | F22: =IF(Config!$G$2=0,0,IF(AND(ABS(($A22-Config!$F$2)/Config!$G$2)>2,ABS(($A22-Config!$F$2)/Config!$G$2)<=3),$D22,0)) | G22: =IF(Config!$G$2=0,0,IF(ABS(($A22-Config!$F$2)/Config!$G$2)>3,$D22,0)) | H22: =IFERROR(NORM.DIST($A22,Config!$F$2,Config!$G$2,FALSE)*Config!$D$2*Config!$J$2,0)
A23: =Config!$K$2+21*Config!$J$2+Config!$J$2/2 | B23: =$A23-Config!$J$2/2 | C23: =$A23+Config!$J$2/2 | D23: =COUNTIFS(RawData!$C$2:$C$941,"LT",RawData!$G$2:$G$941,">="&$B23,RawData!$G$2:$G$941,"<"&$C23,RawData!$G$2:$G$941,"<>0") | E23: =IF(Config!$G$2=0,0,IF(ABS(($A23-Config!$F$2)/Config!$G$2)<=2,$D23,0)) | F23: =IF(Config!$G$2=0,0,IF(AND(ABS(($A23-Config!$F$2)/Config!$G$2)>2,ABS(($A23-Config!$F$2)/Config!$G$2)<=3),$D23,0)) | G23: =IF(Config!$G$2=0,0,IF(ABS(($A23-Config!$F$2)/Config!$G$2)>3,$D23,0)) | H23: =IFERROR(NORM.DIST($A23,Config!$F$2,Config!$G$2,FALSE)*Config!$D$2*Config!$J$2,0)
A24: =Config!$K$2+22*Config!$J$2+Config!$J$2/2 | B24: =$A24-Config!$J$2/2 | C24: =$A24+Config!$J$2/2 | D24: =COUNTIFS(RawData!$C$2:$C$941,"LT",RawData!$G$2:$G$941,">="&$B24,RawData!$G$2:$G$941,"<"&$C24,RawData!$G$2:$G$941,"<>0") | E24: =IF(Config!$G$2=0,0,IF(ABS(($A24-Config!$F$2)/Config!$G$2)<=2,$D24,0)) | F24: =IF(Config!$G$2=0,0,IF(AND(ABS(($A24-Config!$F$2)/Config!$G$2)>2,ABS(($A24-Config!$F$2)/Config!$G$2)<=3),$D24,0)) | G24: =IF(Config!$G$2=0,0,IF(ABS(($A24-Config!$F$2)/Config!$G$2)>3,$D24,0)) | H24: =IFERROR(NORM.DIST($A24,Config!$F$2,Config!$G$2,FALSE)*Config!$D$2*Config!$J$2,0)
A25: =Config!$K$2+23*Config!$J$2+Config!$J$2/2 | B25: =$A25-Config!$J$2/2 | C25: =$A25+Config!$J$2/2 | D25: =COUNTIFS(RawData!$C$2:$C$941,"LT",RawData!$G$2:$G$941,">="&$B25,RawData!$G$2:$G$941,"<"&$C25,RawData!$G$2:$G$941,"<>0") | E25: =IF(Config!$G$2=0,0,IF(ABS(($A25-Config!$F$2)/Config!$G$2)<=2,$D25,0)) | F25: =IF(Config!$G$2=0,0,IF(AND(ABS(($A25-Config!$F$2)/Config!$G$2)>2,ABS(($A25-Config!$F$2)/Config!$G$2)<=3),$D25,0)) | G25: =IF(Config!$G$2=0,0,IF(ABS(($A25-Config!$F$2)/Config!$G$2)>3,$D25,0)) | H25: =IFERROR(NORM.DIST($A25,Config!$F$2,Config!$G$2,FALSE)*Config!$D$2*Config!$J$2,0)
A26: =Config!$K$2+24*Config!$J$2+Config!$J$2/2 | B26: =$A26-Config!$J$2/2 | C26: =$A26+Config!$J$2/2 | D26: =COUNTIFS(RawData!$C$2:$C$941,"LT",RawData!$G$2:$G$941,">="&$B26,RawData!$G$2:$G$941,"<"&$C26,RawData!$G$2:$G$941,"<>0") | E26: =IF(Config!$G$2=0,0,IF(ABS(($A26-Config!$F$2)/Config!$G$2)<=2,$D26,0)) | F26: =IF(Config!$G$2=0,0,IF(AND(ABS(($A26-Config!$F$2)/Config!$G$2)>2,ABS(($A26-Config!$F$2)/Config!$G$2)<=3),$D26,0)) | G26: =IF(Config!$G$2=0,0,IF(ABS(($A26-Config!$F$2)/Config!$G$2)>3,$D26,0)) | H26: =IFERROR(NORM.DIST($A26,Config!$F$2,Config!$G$2,FALSE)*Config!$D$2*Config!$J$2,0)
A27: =Config!$K$2+25*Config!$J$2+Config!$J$2/2 | B27: =$A27-Config!$J$2/2 | C27: =$A27+Config!$J$2/2 | D27: =COUNTIFS(RawData!$C$2:$C$941,"LT",RawData!$G$2:$G$941,">="&$B27,RawData!$G$2:$G$941,"<"&$C27,RawData!$G$2:$G$941,"<>0") | E27: =IF(Config!$G$2=0,0,IF(ABS(($A27-Config!$F$2)/Config!$G$2)<=2,$D27,0)) | F27: =IF(Config!$G$2=0,0,IF(AND(ABS(($A27-Config!$F$2)/Config!$G$2)>2,ABS(($A27-Config!$F$2)/Config!$G$2)<=3),$D27,0)) | G27: =IF(Config!$G$2=0,0,IF(ABS(($A27-Config!$F$2)/Config!$G$2)>3,$D27,0)) | H27: =IFERROR(NORM.DIST($A27,Config!$F$2,Config!$G$2,FALSE)*Config!$D$2*Config!$J$2,0)
A28: =Config!$K$2+26*Config!$J$2+Config!$J$2/2 | B28: =$A28-Config!$J$2/2 | C28: =$A28+Config!$J$2/2 | D28: =COUNTIFS(RawData!$C$2:$C$941,"LT",RawData!$G$2:$G$941,">="&$B28,RawData!$G$2:$G$941,"<"&$C28,RawData!$G$2:$G$941,"<>0") | E28: =IF(Config!$G$2=0,0,IF(ABS(($A28-Config!$F$2)/Config!$G$2)<=2,$D28,0)) | F28: =IF(Config!$G$2=0,0,IF(AND(ABS(($A28-Config!$F$2)/Config!$G$2)>2,ABS(($A28-Config!$F$2)/Config!$G$2)<=3),$D28,0)) | G28: =IF(Config!$G$2=0,0,IF(ABS(($A28-Config!$F$2)/Config!$G$2)>3,$D28,0)) | H28: =IFERROR(NORM.DIST($A28,Config!$F$2,Config!$G$2,FALSE)*Config!$D$2*Config!$J$2,0)
A29: =Config!$K$2+27*Config!$J$2+Config!$J$2/2 | B29: =$A29-Config!$J$2/2 | C29: =$A29+Config!$J$2/2 | D29: =COUNTIFS(RawData!$C$2:$C$941,"LT",RawData!$G$2:$G$941,">="&$B29,RawData!$G$2:$G$941,"<"&$C29,RawData!$G$2:$G$941,"<>0") | E29: =IF(Config!$G$2=0,0,IF(ABS(($A29-Config!$F$2)/Config!$G$2)<=2,$D29,0)) | F29: =IF(Config!$G$2=0,0,IF(AND(ABS(($A29-Config!$F$2)/Config!$G$2)>2,ABS(($A29-Config!$F$2)/Config!$G$2)<=3),$D29,0)) | G29: =IF(Config!$G$2=0,0,IF(ABS(($A29-Config!$F$2)/Config!$G$2)>3,$D29,0)) | H29: =IFERROR(NORM.DIST($A29,Config!$F$2,Config!$G$2,FALSE)*Config!$D$2*Config!$J$2,0)
A30: =Config!$K$2+28*Config!$J$2+Config!$J$2/2 | B30: =$A30-Config!$J$2/2 | C30: =$A30+Config!$J$2/2 | D30: =COUNTIFS(RawData!$C$2:$C$941,"LT",RawData!$G$2:$G$941,">="&$B30,RawData!$G$2:$G$941,"<"&$C30,RawData!$G$2:$G$941,"<>0") | E30: =IF(Config!$G$2=0,0,IF(ABS(($A30-Config!$F$2)/Config!$G$2)<=2,$D30,0)) | F30: =IF(Config!$G$2=0,0,IF(AND(ABS(($A30-Config!$F$2)/Config!$G$2)>2,ABS(($A30-Config!$F$2)/Config!$G$2)<=3),$D30,0)) | G30: =IF(Config!$G$2=0,0,IF(ABS(($A30-Config!$F$2)/Config!$G$2)>3,$D30,0)) | H30: =IFERROR(NORM.DIST($A30,Config!$F$2,Config!$G$2,FALSE)*Config!$D$2*Config!$J$2,0)
A31: =Config!$K$2+29*Config!$J$2+Config!$J$2/2 | B31: =$A31-Config!$J$2/2 | C31: =$A31+Config!$J$2/2 | D31: =COUNTIFS(RawData!$C$2:$C$941,"LT",RawData!$G$2:$G$941,">="&$B31,RawData!$G$2:$G$941,"<"&$C31,RawData!$G$2:$G$941,"<>0") | E31: =IF(Config!$G$2=0,0,IF(ABS(($A31-Config!$F$2)/Config!$G$2)<=2,$D31,0)) | F31: =IF(Config!$G$2=0,0,IF(AND(ABS(($A31-Config!$F$2)/Config!$G$2)>2,ABS(($A31-Config!$F$2)/Config!$G$2)<=3),$D31,0)) | G31: =IF(Config!$G$2=0,0,IF(ABS(($A31-Config!$F$2)/Config!$G$2)>3,$D31,0)) | H31: =IFERROR(NORM.DIST($A31,Config!$F$2,Config!$G$2,FALSE)*Config!$D$2*Config!$J$2,0)
A33: BinCenter | B33: BinLo | C33: BinHi | D33: TotalCount | E33: Normal | F33: Warning(2-3s) | G33: Outlier(>3s) | H33: CurveY
A34: =Config!$K$3+0*Config!$J$3+Config!$J$3/2 | B34: =$A34-Config!$J$3/2 | C34: =$A34+Config!$J$3/2 | D34: =COUNTIFS(RawData!$C$2:$C$941,"LT",RawData!$H$2:$H$941,">="&$B34,RawData!$H$2:$H$941,"<"&$C34,RawData!$H$2:$H$941,"<>0") | E34: =IF(Config!$G$3=0,0,IF(ABS(($A34-Config!$F$3)/Config!$G$3)<=2,$D34,0)) | F34: =IF(Config!$G$3=0,0,IF(AND(ABS(($A34-Config!$F$3)/Config!$G$3)>2,ABS(($A34-Config!$F$3)/Config!$G$3)<=3),$D34,0)) | G34: =IF(Config!$G$3=0,0,IF(ABS(($A34-Config!$F$3)/Config!$G$3)>3,$D34,0)) | H34: =IFERROR(NORM.DIST($A34,Config!$F$3,Config!$G$3,FALSE)*Config!$D$3*Config!$J$3,0)
